Workbook

Sheet Navigation
B2: Claire Studio — FP&A Portfolio Model
B3: Kate Kucherova | Portfolio Project 2026 | CMA Candidate
B5: About This Project
B6: Business: | C6: Claire — Studio of Physical & Aesthetic Development. Children's fitness, dance & martial arts. Bataysk, Russia. Nov 2019 – Jul 2022.
B7: Data source: | C7: This workbook is based on cleaned Claire Studio financial records. Model_Data supports the monthly P&L, dashboard, KPIs, and financial schedules. Ballet shoe COGS uses a weighted-average estimate.
B8: What was built: | C8: Full FP&A model: monthly P&L, KPIs, budget vs actual, variance analysis, unit economics, break-even, management financials, accounting schedules.
B9: Skills shown: | C9: Financial data cleanup, revenue and expense classification, COGS and margin analysis, budgeting, variance explanation, unit economics, and accounting treatment.
B11: Budget Methodology Note
B12: The 2021 management budget was prepared using the late-2020 run-rate, adjusted for second hall expansion rent and utilities, expected program enrollment growth, fixed payroll, and planned merchandise activity.
B14: Tab | C14: What You'll Find
B15: Business_Overview | C15: Business snapshot, programs, pricing, startup investment, key assumptions
B16: Management_Dashboard | C16: KPI summary, revenue trend, program mix, budget check — first visual impression
B17: Monthly_P&L | C17: Month-by-month P&L: class revenue by program, merchandise, COGS, operating expenses, NOI
B18: Annual_KPIs | C18: Annual revenue by program, margins, and KPIs by year
B19: Budget_vs_Actual | C19: 2021 monthly and annual budget vs actual with F/U flags
B20: Variance_Commentary | C20: Plain-English management commentary explaining 2021 results vs budget
B21: Second_Hall_BreakEven | C21: Break-even analysis for the second hall expansion decision
B22: Management_Financials | C22: Income statement, cash flow, and financial position — annual view
B23: Cost_Per_Class_Model | C23: Unit economics: revenue per class, contribution margin, instructor cost logic
B24: Accounting_Treatment | C24: How each category was classified — cash to accrual bridge
B25: Journal_Entries | C25: Representative month-end journal entries with debit/credit/balance check
B26: ——— Supporting Data Tabs ———
B27: Budget_Assumptions | C27: Monthly budget build-up by line item supporting Budget_vs_Actual | D27: Supporting reference
B28: Inventory_Rollforward | C28: Merchandise margin and COGS support schedule | D28: Supporting reference
B29: Fixed_Asset_Depreciation | C29: Straight-line depreciation schedule for equipment and improvements | D29: Supporting reference
B30: Model_Data | C30: Structured monthly source data. Feeds Monthly_PL and all downstream tabs. Do not edit. | D30: Data source
B32: Portfolio Version — 16 tabs | Full model with audit log, correction history, and business valuation available on request.

Sheet Business_Overview
A1: Claire Studio — Business Overview & Key Assumptions
A2: Bataysk | Operating records: Nov 2019 – Jul 2022 | Financial Case Study Portfolio | Amounts shown in $
A3: Claire Children’s Dance Studio was a service-based children’s activity business that generated revenue primarily from recurring class payments for dance, fitness, gymnastics, and karate programs.
A4: Business Snapshot | E4: Founders & Roles | H4: Timeline
A5: Business name | B5: Claire — Studio of Physical & Aesthetic Development | E5: Kate Kucherova | F5: Co-founder, owner, financial manager | H5: Nov 2019 | I5: Studio opened with Hall 1; choreography and gymnastics programs launched
A6: Trade name | B6: Claire | E6: Teaching role | F6: Fitness instructor — no salary drawn | H6: Dec 2019 | I6: First full operating month; setup costs exceeded early revenue
A7: Location | B7: Bataysk, Rostov Oblast, Russia | E7: Finance role | F7: P&L, budgeting, cash flow, payroll, vendors | H7: Jan–Mar 2020 | I7: Enrollment and revenue grew; fitness program added
A8: Business type | B8: Partnership — 2 co-founders | E8: Sveta Strelnikova | F8: Co-founder, choreography partner | H8: Apr–May 2020 | I8: COVID closure period; no operating revenue
A9: Legal form | B9: Sole proprietor, simplified tax regime | E9: Qualification | F9: Master of Sports in Gymnastics | H9: Jun 2020 | I9: Studio reopened; choreography and fitness activity resumed
A10: Industry | B10: Children's fitness, dance & martial arts | E10: Teaching role | F10: Lead choreography — 3 groups | H10: Sep 2020 | I10: Karate program launched; instructor revenue-share model introduced
A11: Currency shown | B11: Presentation currency: $ | E11: Compensation | F11: $750/mo salary + profit distribution | H11: Early 2021 | I11: Hall 2 leased to expand capacity and support subrental income
A12: Data source | B12: Clean Cash Ledger, tax receipts, owner records, owner recollection | E12: Exit | F12: Business operations ended in July 2022 after owner relocation to the United States. | H12: Apr 2021 | I12: Strong spring performance month with revenue above $12K
H13: May 2021 | I13: Fitness pricing increased by 50%
H14: Sep 2021 | I14: Choreography and karate pricing increased by 25%
H15: Jun–Jul 2022 | I15: Business wind-down and transition period
H16: Jul 2022 | I16: Model period ends after business operations transitioned
A18: Program Details & Pricing
A19: Program | B19: Groups | C19: Students/Group | D19: Capacity | E19: Days/Week | F19: Sessions/Mo | G19: Price at Launch ($) | H19: Revised Price ($) | I19: Notes
A20: Choreography | B20: 3 | C20: 15 | D20: 45 | E20: 3 | F20: 36 | G20: $250 | H20: $312.50 (Sep 2021) | I20: Instructor is co-founder, Core revenue stream throughout
A21: Fitness | B21: 2 | C21: 10 | D21: 20 | E21: 2 | F21: 16 | G21: $125 | H21: $187.50 (May 2021) | I21: Instructor is founder, zero direct labor cost
A22: Karate | B22: 2 | C22: 15 | D22: 30 | E22: 3 | F22: 24 | G22: $250 | H22: $312.50 (Sep 2021) | I22: Instructor revenue share: 40% at launch, revised to 50% from Sep 2021
A23: Gymnastics | B23: 1 | C23: 12 | D23: 12 | E23: 2 | F23: 8 | G23: $250 | H23: Discontinued | I23: Nov 2019–Mar 2020. Phased out after COVID
A24: Hall Rental | B24: — | C24: — | D24: — | E24: — | F24: — | G24: Variable | H24: — | I24: Subrental of Hall 2 from early 2021
A26: Startup Investment — Opening Costs (Nov 2019)
A27: Category | B27: Description | C27: Amount ($) | D27: Accounting Treatment | E27: Notes
A28: Equipment & Fixtures | B28: Mirrors, mats, benches, wardrobes, chairs, curtains | C28: 3646 | D28: Capitalize & depreciate | E28: Mirror 7yr; furniture 5yr; mats 3yr
A29: Leasehold Improvements | B29: Flooring, painting, installed lighting | C29: 522 | D29: Amortize over lease | E29: 3-year lease term
A30: Advertising | B30: Print ads, Facebook, flyers, business cards | C30: 724 | D30: Expense at launch | E30: Consumed immediately
A31: Rent first month | B31: Security deposit + first month Hall 1 | C31: 2750 | D31: Prepaid rent / deposit | E31: First month expensed Dec 2019
A32: Office & Signage | B32: Signs, frames, keys, shoe covers, hardware | C32: 704 | D32: Expense at launch | E32: Below capitalization threshold
A33: TOTAL | C33: =SUM(C28:C32) -> 8346 | E33: Opening investment estimate
A35: Key Assumptions & Methodology Notes
A36: Exchange rate | B36: All amounts shown in $ for portfolio presentation.
A37: Missing periods | B37: Apr–May 2020 unavailable — studio closed (COVID lockdown). Excluded from ledger; impact analyzed in Variance Analysis tab.
A38: Payroll classification | B38: Partner fixed salary: $750/mo = Payroll Expense; above fixed salary = Partner Distribution (equity). Karate instructor: revenue share = operating expense.
A39: Reconstructed data | B39: Opening budget and some early 2020 figures reconstructed from owner recollection. All reconstructed items are noted where they appear.
A40: Depreciation | B40: Mirror + install: 7yr straight-line ($27/mo). Other equipment: 5yr ($23/mo). Leasehold improvements: 3yr ($15/mo). Total: ~$65/month from Jan 2020.

Sheet Management_Dashboard
A1: Claire Studio FP&A and Small Business Finance Model — Management Dashboard
A2: Built from real small-business operating records. Source data cleaned and adapted into U.S.-style presentation dollars.
A4: KPI | B4: Value | C4: Interpretation
A5: All-period Revenue | B5: ='Monthly_P&L'!AH26 -> 275336.48 | C5: Total revenue from monthly P&L
A6: All-period NOI | B6: ='Monthly_P&L'!AH48 -> 84989.86 | C6: Net operating income / cash flow before owner items
A7: All-period Margin | B7: ='Monthly_P&L'!AH54 -> 0.30867635 | C7: NOI ÷ Revenue
A8: 2021 Revenue | B8: =Annual_KPIs!D16 -> 120892.1 | C8: Best full-year baseline
A9: 2022 Avg Monthly Revenue | B9: =Annual_KPIs!E37 -> 11518.84 | C9: Partial year run-rate through July
A10: Cumulative Cash After Owners | B10: =Management_Financials!F21 -> 35018.11 | C10: After owner contributions/distributions
A13: Period | B13: Revenue | C13: Net Operating Income | D13: Net Margin % | F13: Expense Driver | G13: All-Period Amount
A14: 2019-11 | B14: =INDEX('Monthly_P&L'!$C$26:$AG$26,1,MATCH($A14,'Monthly_P&L'!$C$3:$AG$3,0)) -> 1800 | C14: =INDEX('Monthly_P&L'!$C$48:$AG$48,1,MATCH($A14,'Monthly_P&L'!$C$3:$AG$3,0)) -> 1237.4 | D14: =IF(B14<>0,C14/B14,"") -> 0.68744444 | F14: Payroll | G14: ='Monthly_P&L'!AH34 -> 41095.62
A15: 2019-12 | B15: =INDEX('Monthly_P&L'!$C$26:$AG$26,1,MATCH($A15,'Monthly_P&L'!$C$3:$AG$3,0)) -> 2775 | C15: =INDEX('Monthly_P&L'!$C$48:$AG$48,1,MATCH($A15,'Monthly_P&L'!$C$3:$AG$3,0)) -> -1163.52 | D15: =IF(B15<>0,C15/B15,"") -> -0.41928649 | F15: Rent | G15: ='Monthly_P&L'!AH40 -> 110229.51
A16: 2020-01 | B16: =INDEX('Monthly_P&L'!$C$26:$AG$26,1,MATCH($A16,'Monthly_P&L'!$C$3:$AG$3,0)) -> 5475 | C16: =INDEX('Monthly_P&L'!$C$48:$AG$48,1,MATCH($A16,'Monthly_P&L'!$C$3:$AG$3,0)) -> 1240.01 | D16: =IF(B16<>0,C16/B16,"") -> 0.22648584 | F16: Utilities | G16: ='Monthly_P&L'!AH41 -> 13436.11
A17: 2020-02 | B17: =INDEX('Monthly_P&L'!$C$26:$AG$26,1,MATCH($A17,'Monthly_P&L'!$C$3:$AG$3,0)) -> 4937.5 | C17: =INDEX('Monthly_P&L'!$C$48:$AG$48,1,MATCH($A17,'Monthly_P&L'!$C$3:$AG$3,0)) -> 1030.59 | D17: =IF(B17<>0,C17/B17,"") -> 0.20872709 | F17: Advertising | G17: ='Monthly_P&L'!AH42 -> 6484.01
A18: 2020-03 | B18: =INDEX('Monthly_P&L'!$C$26:$AG$26,1,MATCH($A18,'Monthly_P&L'!$C$3:$AG$3,0)) -> 5268.75 | C18: =INDEX('Monthly_P&L'!$C$48:$AG$48,1,MATCH($A18,'Monthly_P&L'!$C$3:$AG$3,0)) -> 205.84 | D18: =IF(B18<>0,C18/B18,"") -> 0.03906809 | F18: Tax | G18: ='Monthly_P&L'!AH43 -> 2245.95
A19: 2020-06 | B19: =INDEX('Monthly_P&L'!$C$26:$AG$26,1,MATCH($A19,'Monthly_P&L'!$C$3:$AG$3,0)) -> 5243.75 | C19: =INDEX('Monthly_P&L'!$C$48:$AG$48,1,MATCH($A19,'Monthly_P&L'!$C$3:$AG$3,0)) -> 1713.61 | D19: =IF(B19<>0,C19/B19,"") -> 0.32679094 | F19: COGS | G19: ='Monthly_P&L'!AH31 -> 4213.13
A20: 2020-07 | B20: =INDEX('Monthly_P&L'!$C$26:$AG$26,1,MATCH($A20,'Monthly_P&L'!$C$3:$AG$3,0)) -> 6550 | C20: =INDEX('Monthly_P&L'!$C$48:$AG$48,1,MATCH($A20,'Monthly_P&L'!$C$3:$AG$3,0)) -> 3500.89 | D20: =IF(B20<>0,C20/B20,"") -> 0.53448702 | F20: Other OpEx | G20: ='Monthly_P&L'!AH45 -> 6461.81
A21: 2020-08 | B21: =INDEX('Monthly_P&L'!$C$26:$AG$26,1,MATCH($A21,'Monthly_P&L'!$C$3:$AG$3,0)) -> 6343.75 | C21: =INDEX('Monthly_P&L'!$C$48:$AG$48,1,MATCH($A21,'Monthly_P&L'!$C$3:$AG$3,0)) -> 2446.37 | D21: =IF(B21<>0,C21/B21,"") -> 0.38563468
A22: 2020-09 | B22: =INDEX('Monthly_P&L'!$C$26:$AG$26,1,MATCH($A22,'Monthly_P&L'!$C$3:$AG$3,0)) -> 10837.5 | C22: =INDEX('Monthly_P&L'!$C$48:$AG$48,1,MATCH($A22,'Monthly_P&L'!$C$3:$AG$3,0)) -> 2820.13 | D22: =IF(B22<>0,C22/B22,"") -> 0.26021961
A23: 2020-10 | B23: =INDEX('Monthly_P&L'!$C$26:$AG$26,1,MATCH($A23,'Monthly_P&L'!$C$3:$AG$3,0)) -> 8568.75 | C23: =INDEX('Monthly_P&L'!$C$48:$AG$48,1,MATCH($A23,'Monthly_P&L'!$C$3:$AG$3,0)) -> 4702.37 | D23: =IF(B23<>0,C23/B23,"") -> 0.54878133
A24: 2020-11 | B24: =INDEX('Monthly_P&L'!$C$26:$AG$26,1,MATCH($A24,'Monthly_P&L'!$C$3:$AG$3,0)) -> 7443.75 | C24: =INDEX('Monthly_P&L'!$C$48:$AG$48,1,MATCH($A24,'Monthly_P&L'!$C$3:$AG$3,0)) -> 1951.97 | D24: =IF(B24<>0,C24/B24,"") -> 0.26222939
A25: 2020-12 | B25: =INDEX('Monthly_P&L'!$C$26:$AG$26,1,MATCH($A25,'Monthly_P&L'!$C$3:$AG$3,0)) -> 8568.75 | C25: =INDEX('Monthly_P&L'!$C$48:$AG$48,1,MATCH($A25,'Monthly_P&L'!$C$3:$AG$3,0)) -> 2977.75 | D25: =IF(B25<>0,C25/B25,"") -> 0.34751276
A26: 2021-01 | B26: =INDEX('Monthly_P&L'!$C$26:$AG$26,1,MATCH($A26,'Monthly_P&L'!$C$3:$AG$3,0)) -> 6631.25 | C26: =INDEX('Monthly_P&L'!$C$48:$AG$48,1,MATCH($A26,'Monthly_P&L'!$C$3:$AG$3,0)) -> 2693.8 | D26: =IF(B26<>0,C26/B26,"") -> 0.40622809
A27: 2021-02 | B27: =INDEX('Monthly_P&L'!$C$26:$AG$26,1,MATCH($A27,'Monthly_P&L'!$C$3:$AG$3,0)) -> 6699.24 | C27: =INDEX('Monthly_P&L'!$C$48:$AG$48,1,MATCH($A27,'Monthly_P&L'!$C$3:$AG$3,0)) -> 265.65 | D27: =IF(B27<>0,C27/B27,"") -> 0.039653752
A28: 2021-03 | B28: =INDEX('Monthly_P&L'!$C$26:$AG$26,1,MATCH($A28,'Monthly_P&L'!$C$3:$AG$3,0)) -> 11406.87 | C28: =INDEX('Monthly_P&L'!$C$48:$AG$48,1,MATCH($A28,'Monthly_P&L'!$C$3:$AG$3,0)) -> 3758.72 | D28: =IF(B28<>0,C28/B28,"") -> 0.32951371
A29: 2021-04 | B29: =INDEX('Monthly_P&L'!$C$26:$AG$26,1,MATCH($A29,'Monthly_P&L'!$C$3:$AG$3,0)) -> 12859.37 | C29: =INDEX('Monthly_P&L'!$C$48:$AG$48,1,MATCH($A29,'Monthly_P&L'!$C$3:$AG$3,0)) -> 3549.16 | D29: =IF(B29<>0,C29/B29,"") -> 0.27599797
A30: 2021-05 | B30: =INDEX('Monthly_P&L'!$C$26:$AG$26,1,MATCH($A30,'Monthly_P&L'!$C$3:$AG$3,0)) -> 10931.25 | C30: =INDEX('Monthly_P&L'!$C$48:$AG$48,1,MATCH($A30,'Monthly_P&L'!$C$3:$AG$3,0)) -> 2818.92 | D30: =IF(B30<>0,C30/B30,"") -> 0.25787719
A31: 2021-06 | B31: =INDEX('Monthly_P&L'!$C$26:$AG$26,1,MATCH($A31,'Monthly_P&L'!$C$3:$AG$3,0)) -> 9301.25 | C31: =INDEX('Monthly_P&L'!$C$48:$AG$48,1,MATCH($A31,'Monthly_P&L'!$C$3:$AG$3,0)) -> 2407.81 | D31: =IF(B31<>0,C31/B31,"") -> 0.25886951
A32: 2021-07 | B32: =INDEX('Monthly_P&L'!$C$26:$AG$26,1,MATCH($A32,'Monthly_P&L'!$C$3:$AG$3,0)) -> 7027.5 | C32: =INDEX('Monthly_P&L'!$C$48:$AG$48,1,MATCH($A32,'Monthly_P&L'!$C$3:$AG$3,0)) -> 488.32 | D32: =IF(B32<>0,C32/B32,"") -> 0.069487015
... A44: 2022-07 | B44: =INDEX('Monthly_P&L'!$C$26:$AG$26,1,MATCH($A44,'Monthly_P&L'!$C$3:$AG$3,0)) -> 3987.5 | C44: =INDEX('Monthly_P&L'!$C$48:$AG$48,1,MATCH($A44,'Monthly_P&L'!$C$3:$AG$3,0)) -> 1081.6 | D44: =IF(B44<>0,C44/B44,"") -> 0.27124765
A46: 2021 Budget Check
A47: Budget Revenue | B47: Actual Revenue | C47: Revenue Variance | D47: Budget NOI | E47: Actual NOI | F47: NOI Variance | G47: Comment
A48: =Budget_vs_Actual!B17 -> 117700 | B48: =Budget_vs_Actual!C17 -> 120892.1 | C48: =Budget_vs_Actual!D17 -> 3192.1 | D48: =Budget_vs_Actual!H17 -> 29650 | E48: =Budget_vs_Actual!I17 -> 32068.49 | F48: =Budget_vs_Actual!J17 -> 2418.49 | G48: Actual NOI beat budget; expansion was supported by revenue growth.

Sheet Monthly_P&L
A1: Claire Studio — Monthly P&L Statement
A2: Amounts shown in $ | Source: Model_Data | Apr–May 2020 excluded (COVID closure) | Ballet shoes use weighted-average estimated COGS; gymnastic suits use recorded costs
C3: 2019-11 | D3: 2019-12 | E3: 2020-01 | F3: 2020-02 | G3: 2020-03 | H3: 2020-06 | I3: 2020-07 | J3: 2020-08 | K3: 2020-09 | L3: 2020-10 | M3: 2020-11 | N3: 2020-12 | O3: 2021-01 | P3: 2021-02 | Q3: 2021-03 | R3: 2021-04 | S3: 2021-05 | T3: 2021-06 | U3: 2021-07 | V3: 2021-08 | W3: 2021-09 | X3: 2021-10 | Y3: 2021-11 | Z3: 2021-12 | AA3: 2022-01 | AB3: 2022-02 | AC3: 2022-03 | AD3: 2022-04 | AE3: 2022-05 | AF3: 2022-06 | AG3: 2022-07
C4: 2019 | D4: 2019 | E4: 2020 | F4: 2020 | G4: 2020 | H4: 2020 | I4: 2020 | J4: 2020 | K4: 2020 | L4: 2020 | M4: 2020 | N4: 2020 | O4: 2021 | P4: 2021 | Q4: 2021 | R4: 2021 | S4: 2021 | T4: 2021 | U4: 2021 | V4: 2021 | W4: 2021 | X4: 2021 | Y4: 2021 | Z4: 2021 | AA4: 2022 | AB4: 2022 | AC4: 2022 | AD4: 2022 | AE4: 2022 | AF4: 2022 | AG4: 2022 | AH4: TOTAL
C5: Nov | D5: Dec | E5: Jan | F5: Feb | G5: Mar | H5: Jun | I5: Jul | J5: Aug | K5: Sep | L5: Oct | M5: Nov | N5: Dec | O5: Jan | P5: Feb | Q5: Mar | R5: Apr | S5: May | T5: Jun | U5: Jul | V5: Aug | W5: Sep | X5: Oct | Y5: Nov | Z5: Dec | AA5: Jan | AB5: Feb | AC5: Mar | AD5: Apr | AE5: May | AF5: Jun | AG5: Jul | AH5: All Periods
A6: Class Revenue
A7: Choreography | B7: 4000 | C7: =IFERROR(INDEX(Model_Data!$A$4:$AG$34,MATCH(C$3,Model_Data!$A$4:$A$34,0),MATCH("Revenue - Choreography",Model_Data!$A$3:$AG$3,0)),"") -> 1375 | D7: =IFERROR(INDEX(Model_Data!$A$4:$AG$34,MATCH(D$3,Model_Data!$A$4:$A$34,0),MATCH("Revenue - Choreography",Model_Data!$A$3:$AG$3,0)),"") -> 1875 | E7: =IFERROR(INDEX(Model_Data!$A$4:$AG$34,MATCH(E$3,Model_Data!$A$4:$A$34,0),MATCH("Revenue - Choreography",Model_Data!$A$3:$AG$3,0)),"") -> 3237.5 | F7: =IFERROR(INDEX(Model_Data!$A$4:$AG$34,MATCH(F$3,Model_Data!$A$4:$A$34,0),MATCH("Revenue - Choreography",Model_Data!$A$3:$AG$3,0)),"") -> 3162.5 | G7: =IFERROR(INDEX(Model_Data!$A$4:$AG$34,MATCH(G$3,Model_Data!$A$4:$A$34,0),MATCH("Revenue - Choreography",Model_Data!$A$3:$AG$3,0)),"") -> 2775 | H7: =IFERROR(INDEX(Model_Data!$A$4:$AG$34,MATCH(H$3,Model_Data!$A$4:$A$34,0),MATCH("Revenue - Choreography",Model_Data!$A$3:$AG$3,0)),"") -> 3612.5 | I7: =IFERROR(INDEX(Model_Data!$A$4:$AG$34,MATCH(I$3,Model_Data!$A$4:$A$34,0),MATCH("Revenue - Choreography",Model_Data!$A$3:$AG$3,0)),"") -> 3312.5 | J7: =IFERROR(INDEX(Model_Data!$A$4:$AG$34,MATCH(J$3,Model_Data!$A$4:$A$34,0),MATCH("Revenue - Choreography",Model_Data!$A$3:$AG$3,0)),"") -> 3006.25 | ... AG7: =IFERROR(INDEX(Model_Data!$A$4:$AG$34,MATCH(AG$3,Model_Data!$A$4:$A$34,0),MATCH("Revenue - Choreography",Model_Data!$A$3:$AG$3,0)),"") -> 3312.5 | AH7: =SUM(C7:AG7) -> 140806.12
A8: Fitness | B8: 4010 | C8: =IFERROR(INDEX(Model_Data!$A$4:$AG$34,MATCH(C$3,Model_Data!$A$4:$A$34,0),MATCH("Revenue - Fitness",Model_Data!$A$3:$AG$3,0)),"") -> 0 | D8: =IFERROR(INDEX(Model_Data!$A$4:$AG$34,MATCH(D$3,Model_Data!$A$4:$A$34,0),MATCH("Revenue - Fitness",Model_Data!$A$3:$AG$3,0)),"") -> 0 | E8: =IFERROR(INDEX(Model_Data!$A$4:$AG$34,MATCH(E$3,Model_Data!$A$4:$A$34,0),MATCH("Revenue - Fitness",Model_Data!$A$3:$AG$3,0)),"") -> 0 | F8: =IFERROR(INDEX(Model_Data!$A$4:$AG$34,MATCH(F$3,Model_Data!$A$4:$A$34,0),MATCH("Revenue - Fitness",Model_Data!$A$3:$AG$3,0)),"") -> 0 | G8: =IFERROR(INDEX(Model_Data!$A$4:$AG$34,MATCH(G$3,Model_Data!$A$4:$A$34,0),MATCH("Revenue - Fitness",Model_Data!$A$3:$AG$3,0)),"") -> 656.25 | H8: =IFERROR(INDEX(Model_Data!$A$4:$AG$34,MATCH(H$3,Model_Data!$A$4:$A$34,0),MATCH("Revenue - Fitness",Model_Data!$A$3:$AG$3,0)),"") -> 1037.5 | I8: =IFERROR(INDEX(Model_Data!$A$4:$AG$34,MATCH(I$3,Model_Data!$A$4:$A$34,0),MATCH("Revenue - Fitness",Model_Data!$A$3:$AG$3,0)),"") -> 1762.5 | J8: =IFERROR(INDEX(Model_Data!$A$4:$AG$34,MATCH(J$3,Model_Data!$A$4:$A$34,0),MATCH("Revenue - Fitness",Model_Data!$A$3:$AG$3,0)),"") -> 2206.25 | ... AG8: =IFERROR(INDEX(Model_Data!$A$4:$AG$34,MATCH(AG$3,Model_Data!$A$4:$A$34,0),MATCH("Revenue - Fitness",Model_Data!$A$3:$AG$3,0)),"") -> 0 | AH8: =SUM(C8:AG8) -> 37925
A9: Karate | B9: 4020 | C9: =IFERROR(INDEX(Model_Data!$A$4:$AG$34,MATCH(C$3,Model_Data!$A$4:$A$34,0),MATCH("Revenue - Karate",Model_Data!$A$3:$AG$3,0)),"") -> 0 | D9: =IFERROR(INDEX(Model_Data!$A$4:$AG$34,MATCH(D$3,Model_Data!$A$4:$A$34,0),MATCH("Revenue - Karate",Model_Data!$A$3:$AG$3,0)),"") -> 0 | E9: =IFERROR(INDEX(Model_Data!$A$4:$AG$34,MATCH(E$3,Model_Data!$A$4:$A$34,0),MATCH("Revenue - Karate",Model_Data!$A$3:$AG$3,0)),"") -> 0 | F9: =IFERROR(INDEX(Model_Data!$A$4:$AG$34,MATCH(F$3,Model_Data!$A$4:$A$34,0),MATCH("Revenue - Karate",Model_Data!$A$3:$AG$3,0)),"") -> 0 | G9: =IFERROR(INDEX(Model_Data!$A$4:$AG$34,MATCH(G$3,Model_Data!$A$4:$A$34,0),MATCH("Revenue - Karate",Model_Data!$A$3:$AG$3,0)),"") -> 0 | H9: =IFERROR(INDEX(Model_Data!$A$4:$AG$34,MATCH(H$3,Model_Data!$A$4:$A$34,0),MATCH("Revenue - Karate",Model_Data!$A$3:$AG$3,0)),"") -> 0 | I9: =IFERROR(INDEX(Model_Data!$A$4:$AG$34,MATCH(I$3,Model_Data!$A$4:$A$34,0),MATCH("Revenue - Karate",Model_Data!$A$3:$AG$3,0)),"") -> 0 | J9: =IFERROR(INDEX(Model_Data!$A$4:$AG$34,MATCH(J$3,Model_Data!$A$4:$A$34,0),MATCH("Revenue - Karate",Model_Data!$A$3:$AG$3,0)),"") -> 0 | ... AG9: =IFERROR(INDEX(Model_Data!$A$4:$AG$34,MATCH(AG$3,Model_Data!$A$4:$A$34,0),MATCH("Revenue - Karate",Model_Data!$A$3:$AG$3,0)),"") -> 625 | AH9: =SUM(C9:AG9) -> 58418.75
A10: Gymnastics | B10: 4030 | C10: =IFERROR(INDEX(Model_Data!$A$4:$AG$34,MATCH(C$3,Model_Data!$A$4:$A$34,0),MATCH("Revenue - Gymnastics",Model_Data!$A$3:$AG$3,0)),"") -> 300 | D10: =IFERROR(INDEX(Model_Data!$A$4:$AG$34,MATCH(D$3,Model_Data!$A$4:$A$34,0),MATCH("Revenue - Gymnastics",Model_Data!$A$3:$AG$3,0)),"") -> 900 | E10: =IFERROR(INDEX(Model_Data!$A$4:$AG$34,MATCH(E$3,Model_Data!$A$4:$A$34,0),MATCH("Revenue - Gymnastics",Model_Data!$A$3:$AG$3,0)),"") -> 1437.5 | F10: =IFERROR(INDEX(Model_Data!$A$4:$AG$34,MATCH(F$3,Model_Data!$A$4:$A$34,0),MATCH("Revenue - Gymnastics",Model_Data!$A$3:$AG$3,0)),"") -> 1075 | G10: =IFERROR(INDEX(Model_Data!$A$4:$AG$34,MATCH(G$3,Model_Data!$A$4:$A$34,0),MATCH("Revenue - Gymnastics",Model_Data!$A$3:$AG$3,0)),"") -> 1475 | H10: =IFERROR(INDEX(Model_Data!$A$4:$AG$34,MATCH(H$3,Model_Data!$A$4:$A$34,0),MATCH("Revenue - Gymnastics",Model_Data!$A$3:$AG$3,0)),"") -> 593.75 | I10: =IFERROR(INDEX(Model_Data!$A$4:$AG$34,MATCH(I$3,Model_Data!$A$4:$A$34,0),MATCH("Revenue - Gymnastics",Model_Data!$A$3:$AG$3,0)),"") -> 1162.5 | J10: =IFERROR(INDEX(Model_Data!$A$4:$AG$34,MATCH(J$3,Model_Data!$A$4:$A$34,0),MATCH("Revenue - Gymnastics",Model_Data!$A$3:$AG$3,0)),"") -> 875 | ... AG10: =IFERROR(INDEX(Model_Data!$A$4:$AG$34,MATCH(AG$3,Model_Data!$A$4:$A$34,0),MATCH("Revenue - Gymnastics",Model_Data!$A$3:$AG$3,0)),"") -> 0 | AH10: =SUM(C10:AG10) -> 7818.75
A11: Total Class Revenue | C11: =SUM(C7:C10) -> 1675 | D11: =SUM(D7:D10) -> 2775 | E11: =SUM(E7:E10) -> 4675 | F11: =SUM(F7:F10) -> 4237.5 | G11: =SUM(G7:G10) -> 4906.25 | H11: =SUM(H7:H10) -> 5243.75 | I11: =SUM(I7:I10) -> 6237.5 | J11: =SUM(J7:J10) -> 6087.5 | ... AH11: =SUM(AH7:AH10) -> 244968.62
A13: Merchandise Revenue
A14: Ballet Shoes | B14: 4060a | C14: =IFERROR(INDEX(Model_Data!$A$4:$AG$34,MATCH(C$3,Model_Data!$A$4:$A$34,0),MATCH("Revenue - Ballet Shoes",Model_Data!$A$3:$AG$3,0)),"") -> 0 | D14: =IFERROR(INDEX(Model_Data!$A$4:$AG$34,MATCH(D$3,Model_Data!$A$4:$A$34,0),MATCH("Revenue - Ballet Shoes",Model_Data!$A$3:$AG$3,0)),"") -> 0 | E14: =IFERROR(INDEX(Model_Data!$A$4:$AG$34,MATCH(E$3,Model_Data!$A$4:$A$34,0),MATCH("Revenue - Ballet Shoes",Model_Data!$A$3:$AG$3,0)),"") -> 225 | F14: =IFERROR(INDEX(Model_Data!$A$4:$AG$34,MATCH(F$3,Model_Data!$A$4:$A$34,0),MATCH("Revenue - Ballet Shoes",Model_Data!$A$3:$AG$3,0)),"") -> 50 | G14: =IFERROR(INDEX(Model_Data!$A$4:$AG$34,MATCH(G$3,Model_Data!$A$4:$A$34,0),MATCH("Revenue - Ballet Shoes",Model_Data!$A$3:$AG$3,0)),"") -> 50 | H14: =IFERROR(INDEX(Model_Data!$A$4:$AG$34,MATCH(H$3,Model_Data!$A$4:$A$34,0),MATCH("Revenue - Ballet Shoes",Model_Data!$A$3:$AG$3,0)),"") -> 0 | I14: =IFERROR(INDEX(Model_Data!$A$4:$AG$34,MATCH(I$3,Model_Data!$A$4:$A$34,0),MATCH("Revenue - Ballet Shoes",Model_Data!$A$3:$AG$3,0)),"") -> 87.5 | J14: =IFERROR(INDEX(Model_Data!$A$4:$AG$34,MATCH(J$3,Model_Data!$A$4:$A$34,0),MATCH("Revenue - Ballet Shoes",Model_Data!$A$3:$AG$3,0)),"") -> 0 | ... AG14: =IFERROR(INDEX(Model_Data!$A$4:$AG$34,MATCH(AG$3,Model_Data!$A$4:$A$34,0),MATCH("Revenue - Ballet Shoes",Model_Data!$A$3:$AG$3,0)),"") -> 0 | AH14: =SUM(C14:AG14) -> 1651.25
A15: Gymnastic Suits | B15: 4060b | C15: =IFERROR(INDEX(Model_Data!$A$4:$AG$34,MATCH(C$3,Model_Data!$A$4:$A$34,0),MATCH("Revenue - Gymnastic Suits",Model_Data!$A$3:$AG$3,0)),"") -> 0 | D15: =IFERROR(INDEX(Model_Data!$A$4:$AG$34,MATCH(D$3,Model_Data!$A$4:$A$34,0),MATCH("Revenue - Gymnastic Suits",Model_Data!$A$3:$AG$3,0)),"") -> 0 | E15: =IFERROR(INDEX(Model_Data!$A$4:$AG$34,MATCH(E$3,Model_Data!$A$4:$A$34,0),MATCH("Revenue - Gymnastic Suits",Model_Data!$A$3:$AG$3,0)),"") -> 375 | F15: =IFERROR(INDEX(Model_Data!$A$4:$AG$34,MATCH(F$3,Model_Data!$A$4:$A$34,0),MATCH("Revenue - Gymnastic Suits",Model_Data!$A$3:$AG$3,0)),"") -> 250 | G15: =IFERROR(INDEX(Model_Data!$A$4:$AG$34,MATCH(G$3,Model_Data!$A$4:$A$34,0),MATCH("Revenue - Gymnastic Suits",Model_Data!$A$3:$AG$3,0)),"") -> 312.5 | H15: =IFERROR(INDEX(Model_Data!$A$4:$AG$34,MATCH(H$3,Model_Data!$A$4:$A$34,0),MATCH("Revenue - Gymnastic Suits",Model_Data!$A$3:$AG$3,0)),"") -> 0 | I15: =IFERROR(INDEX(Model_Data!$A$4:$AG$34,MATCH(I$3,Model_Data!$A$4:$A$34,0),MATCH("Revenue - Gymnastic Suits",Model_Data!$A$3:$AG$3,0)),"") -> 0 | J15: =IFERROR(INDEX(Model_Data!$A$4:$AG$34,MATCH(J$3,Model_Data!$A$4:$A$34,0),MATCH("Revenue - Gymnastic Suits",Model_Data!$A$3:$AG$3,0)),"") -> 243.75 | ... AG15: =IFERROR(INDEX(Model_Data!$A$4:$AG$34,MATCH(AG$3,Model_Data!$A$4:$A$34,0),MATCH("Revenue - Gymnastic Suits",Model_Data!$A$3:$AG$3,0)),"") -> 0 | AH15: =SUM(C15:AG15) -> 4568.75
A16: Merchandise — Other | B16: 4060c | C16: =IFERROR(INDEX(Model_Data!$A$4:$AG$34,MATCH(C$3,Model_Data!$A$4:$A$34,0),MATCH("Revenue - Merchandise - Other",Model_Data!$A$3:$AG$3,0)),"") -> 0 | D16: =IFERROR(INDEX(Model_Data!$A$4:$AG$34,MATCH(D$3,Model_Data!$A$4:$A$34,0),MATCH("Revenue - Merchandise - Other",Model_Data!$A$3:$AG$3,0)),"") -> 0 | E16: =IFERROR(INDEX(Model_Data!$A$4:$AG$34,MATCH(E$3,Model_Data!$A$4:$A$34,0),MATCH("Revenue - Merchandise - Other",Model_Data!$A$3:$AG$3,0)),"") -> 0 | F16: =IFERROR(INDEX(Model_Data!$A$4:$AG$34,MATCH(F$3,Model_Data!$A$4:$A$34,0),MATCH("Revenue - Merchandise - Other",Model_Data!$A$3:$AG$3,0)),"") -> 0 | G16: =IFERROR(INDEX(Model_Data!$A$4:$AG$34,MATCH(G$3,Model_Data!$A$4:$A$34,0),MATCH("Revenue - Merchandise - Other",Model_Data!$A$3:$AG$3,0)),"") -> 0 | H16: =IFERROR(INDEX(Model_Data!$A$4:$AG$34,MATCH(H$3,Model_Data!$A$4:$A$34,0),MATCH("Revenue - Merchandise - Other",Model_Data!$A$3:$AG$3,0)),"") -> 0 | I16: =IFERROR(INDEX(Model_Data!$A$4:$AG$34,MATCH(I$3,Model_Data!$A$4:$A$34,0),MATCH("Revenue - Merchandise - Other",Model_Data!$A$3:$AG$3,0)),"") -> 0 | J16: =IFERROR(INDEX(Model_Data!$A$4:$AG$34,MATCH(J$3,Model_Data!$A$4:$A$34,0),MATCH("Revenue - Merchandise - Other",Model_Data!$A$3:$AG$3,0)),"") -> 0 | ... AG16: =IFERROR(INDEX(Model_Data!$A$4:$AG$34,MATCH(AG$3,Model_Data!$A$4:$A$34,0),MATCH("Revenue - Merchandise - Other",Model_Data!$A$3:$AG$3,0)),"") -> 0 | AH16: =SUM(C16:AG16) -> 0
A17: Total Merchandise Revenue | C17: =SUM(C14:C16) -> 0 | D17: =SUM(D14:D16) -> 0 | E17: =SUM(E14:E16) -> 600 | F17: =SUM(F14:F16) -> 300 | G17: =SUM(G14:G16) -> 362.5 | H17: =SUM(H14:H16) -> 0 | I17: =SUM(I14:I16) -> 87.5 | J17: =SUM(J14:J16) -> 243.75 | ... AH17: =SUM(AH14:AH16) -> 6220
A19: Other Revenue
A20: Hall Rental | B20: 4040 | C20: =IFERROR(INDEX(Model_Data!$A$4:$AG$34,MATCH(C$3,Model_Data!$A$4:$A$34,0),MATCH("Revenue - Hall Rental Income",Model_Data!$A$3:$AG$3,0)),"") -> 0 | D20: =IFERROR(INDEX(Model_Data!$A$4:$AG$34,MATCH(D$3,Model_Data!$A$4:$A$34,0),MATCH("Revenue - Hall Rental Income",Model_Data!$A$3:$AG$3,0)),"") -> 0 | E20: =IFERROR(INDEX(Model_Data!$A$4:$AG$34,MATCH(E$3,Model_Data!$A$4:$A$34,0),MATCH("Revenue - Hall Rental Income",Model_Data!$A$3:$AG$3,0)),"") -> 0 | F20: =IFERROR(INDEX(Model_Data!$A$4:$AG$34,MATCH(F$3,Model_Data!$A$4:$A$34,0),MATCH("Revenue - Hall Rental Income",Model_Data!$A$3:$AG$3,0)),"") -> 0 | G20: =IFERROR(INDEX(Model_Data!$A$4:$AG$34,MATCH(G$3,Model_Data!$A$4:$A$34,0),MATCH("Revenue - Hall Rental Income",Model_Data!$A$3:$AG$3,0)),"") -> 0 | H20: =IFERROR(INDEX(Model_Data!$A$4:$AG$34,MATCH(H$3,Model_Data!$A$4:$A$34,0),MATCH("Revenue - Hall Rental Income",Model_Data!$A$3:$AG$3,0)),"") -> 0 | I20: =IFERROR(INDEX(Model_Data!$A$4:$AG$34,MATCH(I$3,Model_Data!$A$4:$A$34,0),MATCH("Revenue - Hall Rental Income",Model_Data!$A$3:$AG$3,0)),"") -> 0 | J20: =IFERROR(INDEX(Model_Data!$A$4:$AG$34,MATCH(J$3,Model_Data!$A$4:$A$34,0),MATCH("Revenue - Hall Rental Income",Model_Data!$A$3:$AG$3,0)),"") -> 0 | ... AG20: =IFERROR(INDEX(Model_Data!$A$4:$AG$34,MATCH(AG$3,Model_Data!$A$4:$A$34,0),MATCH("Revenue - Hall Rental Income",Model_Data!$A$3:$AG$3,0)),"") -> 50 | AH20: =SUM(C20:AG20) -> 20166.62
A21: Utilities Reimb. | B21: 4050 | C21: =IFERROR(INDEX(Model_Data!$A$4:$AG$34,MATCH(C$3,Model_Data!$A$4:$A$34,0),MATCH("Revenue - Utilities Reimbursement",Model_Data!$A$3:$AG$3,0)),"") -> 0 | D21: =IFERROR(INDEX(Model_Data!$A$4:$AG$34,MATCH(D$3,Model_Data!$A$4:$A$34,0),MATCH("Revenue - Utilities Reimbursement",Model_Data!$A$3:$AG$3,0)),"") -> 0 | E21: =IFERROR(INDEX(Model_Data!$A$4:$AG$34,MATCH(E$3,Model_Data!$A$4:$A$34,0),MATCH("Revenue - Utilities Reimbursement",Model_Data!$A$3:$AG$3,0)),"") -> 0 | F21: =IFERROR(INDEX(Model_Data!$A$4:$AG$34,MATCH(F$3,Model_Data!$A$4:$A$34,0),MATCH("Revenue - Utilities Reimbursement",Model_Data!$A$3:$AG$3,0)),"") -> 0 | G21: =IFERROR(INDEX(Model_Data!$A$4:$AG$34,MATCH(G$3,Model_Data!$A$4:$A$34,0),MATCH("Revenue - Utilities Reimbursement",Model_Data!$A$3:$AG$3,0)),"") -> 0 | H21: =IFERROR(INDEX(Model_Data!$A$4:$AG$34,MATCH(H$3,Model_Data!$A$4:$A$34,0),MATCH("Revenue - Utilities Reimbursement",Model_Data!$A$3:$AG$3,0)),"") -> 0 | I21: =IFERROR(INDEX(Model_Data!$A$4:$AG$34,MATCH(I$3,Model_Data!$A$4:$A$34,0),MATCH("Revenue - Utilities Reimbursement",Model_Data!$A$3:$AG$3,0)),"") -> 0 | J21: =IFERROR(INDEX(Model_Data!$A$4:$AG$34,MATCH(J$3,Model_Data!$A$4:$A$34,0),MATCH("Revenue - Utilities Reimbursement",Model_Data!$A$3:$AG$3,0)),"") -> 0 | ... AG21: =IFERROR(INDEX(Model_Data!$A$4:$AG$34,MATCH(AG$3,Model_Data!$A$4:$A$34,0),MATCH("Revenue - Utilities Reimbursement",Model_Data!$A$3:$AG$3,0)),"") -> 0 | AH21: =SUM(C21:AG21) -> 193.75
A22: Events & Photos | B22: 4070 | C22: =IFERROR(INDEX(Model_Data!$A$4:$AG$34,MATCH(C$3,Model_Data!$A$4:$A$34,0),MATCH("Revenue - Event / Photo Revenue",Model_Data!$A$3:$AG$3,0)),"") -> 0 | D22: =IFERROR(INDEX(Model_Data!$A$4:$AG$34,MATCH(D$3,Model_Data!$A$4:$A$34,0),MATCH("Revenue - Event / Photo Revenue",Model_Data!$A$3:$AG$3,0)),"") -> 0 | E22: =IFERROR(INDEX(Model_Data!$A$4:$AG$34,MATCH(E$3,Model_Data!$A$4:$A$34,0),MATCH("Revenue - Event / Photo Revenue",Model_Data!$A$3:$AG$3,0)),"") -> 0 | F22: =IFERROR(INDEX(Model_Data!$A$4:$AG$34,MATCH(F$3,Model_Data!$A$4:$A$34,0),MATCH("Revenue - Event / Photo Revenue",Model_Data!$A$3:$AG$3,0)),"") -> 0 | G22: =IFERROR(INDEX(Model_Data!$A$4:$AG$34,MATCH(G$3,Model_Data!$A$4:$A$34,0),MATCH("Revenue - Event / Photo Revenue",Model_Data!$A$3:$AG$3,0)),"") -> 0 | H22: =IFERROR(INDEX(Model_Data!$A$4:$AG$34,MATCH(H$3,Model_Data!$A$4:$A$34,0),MATCH("Revenue - Event / Photo Revenue",Model_Data!$A$3:$AG$3,0)),"") -> 0 | I22: =IFERROR(INDEX(Model_Data!$A$4:$AG$34,MATCH(I$3,Model_Data!$A$4:$A$34,0),MATCH("Revenue - Event / Photo Revenue",Model_Data!$A$3:$AG$3,0)),"") -> 0 | J22: =IFERROR(INDEX(Model_Data!$A$4:$AG$34,MATCH(J$3,Model_Data!$A$4:$A$34,0),MATCH("Revenue - Event / Photo Revenue",Model_Data!$A$3:$AG$3,0)),"") -> 0 | ... AG22: =IFERROR(INDEX(Model_Data!$A$4:$AG$34,MATCH(AG$3,Model_Data!$A$4:$A$34,0),MATCH("Revenue - Event / Photo Revenue",Model_Data!$A$3:$AG$3,0)),"") -> 0 | AH22: =SUM(C22:AG22) -> 1490.74
A23: Other | B23: 4080 | C23: =IFERROR(INDEX(Model_Data!$A$4:$AG$34,MATCH(C$3,Model_Data!$A$4:$A$34,0),MATCH("Revenue - Other",Model_Data!$A$3:$AG$3,0)),"") -> 125 | D23: =IFERROR(INDEX(Model_Data!$A$4:$AG$34,MATCH(D$3,Model_Data!$A$4:$A$34,0),MATCH("Revenue - Other",Model_Data!$A$3:$AG$3,0)),"") -> 0 | E23: =IFERROR(INDEX(Model_Data!$A$4:$AG$34,MATCH(E$3,Model_Data!$A$4:$A$34,0),MATCH("Revenue - Other",Model_Data!$A$3:$AG$3,0)),"") -> 200 | F23: =IFERROR(INDEX(Model_Data!$A$4:$AG$34,MATCH(F$3,Model_Data!$A$4:$A$34,0),MATCH("Revenue - Other",Model_Data!$A$3:$AG$3,0)),"") -> 400 | G23: =IFERROR(INDEX(Model_Data!$A$4:$AG$34,MATCH(G$3,Model_Data!$A$4:$A$34,0),MATCH("Revenue - Other",Model_Data!$A$3:$AG$3,0)),"") -> 0 | H23: =IFERROR(INDEX(Model_Data!$A$4:$AG$34,MATCH(H$3,Model_Data!$A$4:$A$34,0),MATCH("Revenue - Other",Model_Data!$A$3:$AG$3,0)),"") -> 0 | I23: =IFERROR(INDEX(Model_Data!$A$4:$AG$34,MATCH(I$3,Model_Data!$A$4:$A$34,0),MATCH("Revenue - Other",Model_Data!$A$3:$AG$3,0)),"") -> 225 | J23: =IFERROR(INDEX(Model_Data!$A$4:$AG$34,MATCH(J$3,Model_Data!$A$4:$A$34,0),MATCH("Revenue - Other",Model_Data!$A$3:$AG$3,0)),"") -> 12.5 | ... AG23: =IFERROR(INDEX(Model_Data!$A$4:$AG$34,MATCH(AG$3,Model_Data!$A$4:$A$34,0),MATCH("Revenue - Other",Model_Data!$A$3:$AG$3,0)),"") -> 0 | AH23: =SUM(C23:AG23) -> 2296.75
A24: Total Other Revenue | C24: =SUM(C20:C23) -> 125 | D24: =SUM(D20:D23) -> 0 | E24: =SUM(E20:E23) -> 200 | F24: =SUM(F20:F23) -> 400 | G24: =SUM(G20:G23) -> 0 | H24: =SUM(H20:H23) -> 0 | I24: =SUM(I20:I23) -> 225 | J24: =SUM(J20:J23) -> 12.5 | ... AH24: =SUM(AH20:AH23) -> 24147.86
A26: TOTAL REVENUE | C26: =SUM(C11,C17,C24) -> 1800 | D26: =SUM(D11,D17,D24) -> 2775 | E26: =SUM(E11,E17,E24) -> 5475 | F26: =SUM(F11,F17,F24) -> 4937.5 | G26: =SUM(G11,G17,G24) -> 5268.75 | H26: =SUM(H11,H17,H24) -> 5243.75 | I26: =SUM(I11,I17,I24) -> 6550 | J26: =SUM(J11,J17,J24) -> 6343.75 | ... AH26: =SUM(AH11,AH17,AH24) -> 275336.48
A28: Cost of Goods Sold (inventory items only)
A29: Ballet Shoes — COGS | B29: 5050 | C29: =IFERROR(INDEX(Model_Data!$A$4:$AG$34,MATCH(C$3,Model_Data!$A$4:$A$34,0),MATCH("Expense - Ballet Shoe Cost",Model_Data!$A$3:$AG$3,0)),"") -> 0 | D29: =IFERROR(INDEX(Model_Data!$A$4:$AG$34,MATCH(D$3,Model_Data!$A$4:$A$34,0),MATCH("Expense - Ballet Shoe Cost",Model_Data!$A$3:$AG$3,0)),"") -> 0 | E29: =IFERROR(INDEX(Model_Data!$A$4:$AG$34,MATCH(E$3,Model_Data!$A$4:$A$34,0),MATCH("Expense - Ballet Shoe Cost",Model_Data!$A$3:$AG$3,0)),"") -> 146.99 | F29: =IFERROR(INDEX(Model_Data!$A$4:$AG$34,MATCH(F$3,Model_Data!$A$4:$A$34,0),MATCH("Expense - Ballet Shoe Cost",Model_Data!$A$3:$AG$3,0)),"") -> 32.66 | G29: =IFERROR(INDEX(Model_Data!$A$4:$AG$34,MATCH(G$3,Model_Data!$A$4:$A$34,0),MATCH("Expense - Ballet Shoe Cost",Model_Data!$A$3:$AG$3,0)),"") -> 32.66 | H29: =IFERROR(INDEX(Model_Data!$A$4:$AG$34,MATCH(H$3,Model_Data!$A$4:$A$34,0),MATCH("Expense - Ballet Shoe Cost",Model_Data!$A$3:$AG$3,0)),"") -> 0 | I29: =IFERROR(INDEX(Model_Data!$A$4:$AG$34,MATCH(I$3,Model_Data!$A$4:$A$34,0),MATCH("Expense - Ballet Shoe Cost",Model_Data!$A$3:$AG$3,0)),"") -> 57.16 | J29: =IFERROR(INDEX(Model_Data!$A$4:$AG$34,MATCH(J$3,Model_Data!$A$4:$A$34,0),MATCH("Expense - Ballet Shoe Cost",Model_Data!$A$3:$AG$3,0)),"") -> 0 | ... AG29: =IFERROR(INDEX(Model_Data!$A$4:$AG$34,MATCH(AG$3,Model_Data!$A$4:$A$34,0),MATCH("Expense - Ballet Shoe Cost",Model_Data!$A$3:$AG$3,0)),"") -> 0 | AH29: =SUM(C29:AG29) -> 1078.75
A30: Gymnastic Suits — COGS | B30: 5010 | C30: =IFERROR(INDEX(Model_Data!$A$4:$AG$34,MATCH(C$3,Model_Data!$A$4:$A$34,0),MATCH("Expense - Gymnastic Suit Cost",Model_Data!$A$3:$AG$3,0)),"") -> 0 | D30: =IFERROR(INDEX(Model_Data!$A$4:$AG$34,MATCH(D$3,Model_Data!$A$4:$A$34,0),MATCH("Expense - Gymnastic Suit Cost",Model_Data!$A$3:$AG$3,0)),"") -> 0 | E30: =IFERROR(INDEX(Model_Data!$A$4:$AG$34,MATCH(E$3,Model_Data!$A$4:$A$34,0),MATCH("Expense - Gymnastic Suit Cost",Model_Data!$A$3:$AG$3,0)),"") -> 234.38 | F30: =IFERROR(INDEX(Model_Data!$A$4:$AG$34,MATCH(F$3,Model_Data!$A$4:$A$34,0),MATCH("Expense - Gymnastic Suit Cost",Model_Data!$A$3:$AG$3,0)),"") -> 0 | G30: =IFERROR(INDEX(Model_Data!$A$4:$AG$34,MATCH(G$3,Model_Data!$A$4:$A$34,0),MATCH("Expense - Gymnastic Suit Cost",Model_Data!$A$3:$AG$3,0)),"") -> 81.25 | H30: =IFERROR(INDEX(Model_Data!$A$4:$AG$34,MATCH(H$3,Model_Data!$A$4:$A$34,0),MATCH("Expense - Gymnastic Suit Cost",Model_Data!$A$3:$AG$3,0)),"") -> 0 | I30: =IFERROR(INDEX(Model_Data!$A$4:$AG$34,MATCH(I$3,Model_Data!$A$4:$A$34,0),MATCH("Expense - Gymnastic Suit Cost",Model_Data!$A$3:$AG$3,0)),"") -> 531.25 | J30: =IFERROR(INDEX(Model_Data!$A$4:$AG$34,MATCH(J$3,Model_Data!$A$4:$A$34,0),MATCH("Expense - Gymnastic Suit Cost",Model_Data!$A$3:$AG$3,0)),"") -> 0 | ... AG30: =IFERROR(INDEX(Model_Data!$A$4:$AG$34,MATCH(AG$3,Model_Data!$A$4:$A$34,0),MATCH("Expense - Gymnastic Suit Cost",Model_Data!$A$3:$AG$3,0)),"") -> 0 | AH30: =SUM(C30:AG30) -> 3134.38
A31: Total COGS | C31: =SUM(C29:C30) -> 0 | D31: =SUM(D29:D30) -> 0 | E31: =SUM(E29:E30) -> 381.37 | F31: =SUM(F29:F30) -> 32.66 | G31: =SUM(G29:G30) -> 113.91 | H31: =SUM(H29:H30) -> 0 | I31: =SUM(I29:I30) -> 588.41 | J31: =SUM(J29:J30) -> 0 | ... AH31: =SUM(AH29:AH30) -> 4213.13
A33: Cost of Services
A34: Payroll — Co-Founder salary + Karate Instructor rev share + substitutes | B34: 5000 | C34: =IFERROR(INDEX(Model_Data!$A$4:$AG$34,MATCH(C$3,Model_Data!$A$4:$A$34,0),MATCH("Expense - Payroll",Model_Data!$A$3:$AG$3,0)),"") -> 0 | D34: =IFERROR(INDEX(Model_Data!$A$4:$AG$34,MATCH(D$3,Model_Data!$A$4:$A$34,0),MATCH("Expense - Payroll",Model_Data!$A$3:$AG$3,0)),"") -> 0 | E34: =IFERROR(INDEX(Model_Data!$A$4:$AG$34,MATCH(E$3,Model_Data!$A$4:$A$34,0),MATCH("Expense - Payroll",Model_Data!$A$3:$AG$3,0)),"") -> 462.5 | F34: =IFERROR(INDEX(Model_Data!$A$4:$AG$34,MATCH(F$3,Model_Data!$A$4:$A$34,0),MATCH("Expense - Payroll",Model_Data!$A$3:$AG$3,0)),"") -> 412.5 | G34: =IFERROR(INDEX(Model_Data!$A$4:$AG$34,MATCH(G$3,Model_Data!$A$4:$A$34,0),MATCH("Expense - Payroll",Model_Data!$A$3:$AG$3,0)),"") -> 150 | H34: =IFERROR(INDEX(Model_Data!$A$4:$AG$34,MATCH(H$3,Model_Data!$A$4:$A$34,0),MATCH("Expense - Payroll",Model_Data!$A$3:$AG$3,0)),"") -> 625 | I34: =IFERROR(INDEX(Model_Data!$A$4:$AG$34,MATCH(I$3,Model_Data!$A$4:$A$34,0),MATCH("Expense - Payroll",Model_Data!$A$3:$AG$3,0)),"") -> 862.5 | J34: =IFERROR(INDEX(Model_Data!$A$4:$AG$34,MATCH(J$3,Model_Data!$A$4:$A$34,0),MATCH("Expense - Payroll",Model_Data!$A$3:$AG$3,0)),"") -> 750 | ... AG34: =IFERROR(INDEX(Model_Data!$A$4:$AG$34,MATCH(AG$3,Model_Data!$A$4:$A$34,0),MATCH("Expense - Payroll",Model_Data!$A$3:$AG$3,0)),"") -> 0 | AH34: =SUM(C34:AG34) -> 41095.62
A35: Class Supplies | B35: 5030 | C35: =IFERROR(INDEX(Model_Data!$A$4:$AG$34,MATCH(C$3,Model_Data!$A$4:$A$34,0),MATCH("Expense - Class Supplies",Model_Data!$A$3:$AG$3,0)),"") -> 0 | D35: =IFERROR(INDEX(Model_Data!$A$4:$AG$34,MATCH(D$3,Model_Data!$A$4:$A$34,0),MATCH("Expense - Class Supplies",Model_Data!$A$3:$AG$3,0)),"") -> 0 | E35: =IFERROR(INDEX(Model_Data!$A$4:$AG$34,MATCH(E$3,Model_Data!$A$4:$A$34,0),MATCH("Expense - Class Supplies",Model_Data!$A$3:$AG$3,0)),"") -> 0 | F35: =IFERROR(INDEX(Model_Data!$A$4:$AG$34,MATCH(F$3,Model_Data!$A$4:$A$34,0),MATCH("Expense - Class Supplies",Model_Data!$A$3:$AG$3,0)),"") -> 50 | G35: =IFERROR(INDEX(Model_Data!$A$4:$AG$34,MATCH(G$3,Model_Data!$A$4:$A$34,0),MATCH("Expense - Class Supplies",Model_Data!$A$3:$AG$3,0)),"") -> 131.25 | H35: =IFERROR(INDEX(Model_Data!$A$4:$AG$34,MATCH(H$3,Model_Data!$A$4:$A$34,0),MATCH("Expense - Class Supplies",Model_Data!$A$3:$AG$3,0)),"") -> 0 | I35: =IFERROR(INDEX(Model_Data!$A$4:$AG$34,MATCH(I$3,Model_Data!$A$4:$A$34,0),MATCH("Expense - Class Supplies",Model_Data!$A$3:$AG$3,0)),"") -> 0 | J35: =IFERROR(INDEX(Model_Data!$A$4:$AG$34,MATCH(J$3,Model_Data!$A$4:$A$34,0),MATCH("Expense - Class Supplies",Model_Data!$A$3:$AG$3,0)),"") -> 87.5 | ... AG35: =IFERROR(INDEX(Model_Data!$A$4:$AG$34,MATCH(AG$3,Model_Data!$A$4:$A$34,0),MATCH("Expense - Class Supplies",Model_Data!$A$3:$AG$3,0)),"") -> 0 | AH35: =SUM(C35:AG35) -> 775
A36: Event & Competition Costs | B36: 5040 | C36: =IFERROR(INDEX(Model_Data!$A$4:$AG$34,MATCH(C$3,Model_Data!$A$4:$A$34,0),MATCH("Expense - Events and Competitions",Model_Data!$A$3:$AG$3,0)),"") -> 0 | D36: =IFERROR(INDEX(Model_Data!$A$4:$AG$34,MATCH(D$3,Model_Data!$A$4:$A$34,0),MATCH("Expense - Events and Competitions",Model_Data!$A$3:$AG$3,0)),"") -> 0 | E36: =IFERROR(INDEX(Model_Data!$A$4:$AG$34,MATCH(E$3,Model_Data!$A$4:$A$34,0),MATCH("Expense - Events and Competitions",Model_Data!$A$3:$AG$3,0)),"") -> 0 | F36: =IFERROR(INDEX(Model_Data!$A$4:$AG$34,MATCH(F$3,Model_Data!$A$4:$A$34,0),MATCH("Expense - Events and Competitions",Model_Data!$A$3:$AG$3,0)),"") -> 0 | G36: =IFERROR(INDEX(Model_Data!$A$4:$AG$34,MATCH(G$3,Model_Data!$A$4:$A$34,0),MATCH("Expense - Events and Competitions",Model_Data!$A$3:$AG$3,0)),"") -> 0 | H36: =IFERROR(INDEX(Model_Data!$A$4:$AG$34,MATCH(H$3,Model_Data!$A$4:$A$34,0),MATCH("Expense - Events and Competitions",Model_Data!$A$3:$AG$3,0)),"") -> 0 | I36: =IFERROR(INDEX(Model_Data!$A$4:$AG$34,MATCH(I$3,Model_Data!$A$4:$A$34,0),MATCH("Expense - Events and Competitions",Model_Data!$A$3:$AG$3,0)),"") -> 0 | J36: =IFERROR(INDEX(Model_Data!$A$4:$AG$34,MATCH(J$3,Model_Data!$A$4:$A$34,0),MATCH("Expense - Events and Competitions",Model_Data!$A$3:$AG$3,0)),"") -> 0 | ... AG36: =IFERROR(INDEX(Model_Data!$A$4:$AG$34,MATCH(AG$3,Model_Data!$A$4:$A$34,0),MATCH("Expense - Events and Competitions",Model_Data!$A$3:$AG$3,0)),"") -> 0 | AH36: =SUM(C36:AG36) -> 197.25
A37: Total Cost of Services | C37: =SUM(C34:C36) -> 0 | D37: =SUM(D34:D36) -> 0 | E37: =SUM(E34:E36) -> 462.5 | F37: =SUM(F34:F36) -> 462.5 | G37: =SUM(G34:G36) -> 281.25 | H37: =SUM(H34:H36) -> 625 | I37: =SUM(I34:I36) -> 862.5 | J37: =SUM(J34:J36) -> 837.5 | ... AH37: =SUM(AH34:AH36) -> 42067.87
A39: Operating Expenses
A40: Rent | B40: 6000 | C40: =IFERROR(INDEX(Model_Data!$A$4:$AG$34,MATCH(C$3,Model_Data!$A$4:$A$34,0),MATCH("Expense - Rent",Model_Data!$A$3:$AG$3,0)),"") -> 0 | D40: =IFERROR(INDEX(Model_Data!$A$4:$AG$34,MATCH(D$3,Model_Data!$A$4:$A$34,0),MATCH("Expense - Rent",Model_Data!$A$3:$AG$3,0)),"") -> 2775 | E40: =IFERROR(INDEX(Model_Data!$A$4:$AG$34,MATCH(E$3,Model_Data!$A$4:$A$34,0),MATCH("Expense - Rent",Model_Data!$A$3:$AG$3,0)),"") -> 2800 | F40: =IFERROR(INDEX(Model_Data!$A$4:$AG$34,MATCH(F$3,Model_Data!$A$4:$A$34,0),MATCH("Expense - Rent",Model_Data!$A$3:$AG$3,0)),"") -> 2800 | G40: =IFERROR(INDEX(Model_Data!$A$4:$AG$34,MATCH(G$3,Model_Data!$A$4:$A$34,0),MATCH("Expense - Rent",Model_Data!$A$3:$AG$3,0)),"") -> 2800 | H40: =IFERROR(INDEX(Model_Data!$A$4:$AG$34,MATCH(H$3,Model_Data!$A$4:$A$34,0),MATCH("Expense - Rent",Model_Data!$A$3:$AG$3,0)),"") -> 1401.38 | I40: =IFERROR(INDEX(Model_Data!$A$4:$AG$34,MATCH(I$3,Model_Data!$A$4:$A$34,0),MATCH("Expense - Rent",Model_Data!$A$3:$AG$3,0)),"") -> 1401.38 | J40: =IFERROR(INDEX(Model_Data!$A$4:$AG$34,MATCH(J$3,Model_Data!$A$4:$A$34,0),MATCH("Expense - Rent",Model_Data!$A$3:$AG$3,0)),"") -> 2800 | ... AG40: =IFERROR(INDEX(Model_Data!$A$4:$AG$34,MATCH(AG$3,Model_Data!$A$4:$A$34,0),MATCH("Expense - Rent",Model_Data!$A$3:$AG$3,0)),"") -> 2441.25 | AH40: =SUM(C40:AG40) -> 110229.51
A41: Utilities | B41: 6010 | C41: =IFERROR(INDEX(Model_Data!$A$4:$AG$34,MATCH(C$3,Model_Data!$A$4:$A$34,0),MATCH("Expense - Utilities",Model_Data!$A$3:$AG$3,0)),"") -> 562.6 | D41: =IFERROR(INDEX(Model_Data!$A$4:$AG$34,MATCH(D$3,Model_Data!$A$4:$A$34,0),MATCH("Expense - Utilities",Model_Data!$A$3:$AG$3,0)),"") -> 702.27 | E41: =IFERROR(INDEX(Model_Data!$A$4:$AG$34,MATCH(E$3,Model_Data!$A$4:$A$34,0),MATCH("Expense - Utilities",Model_Data!$A$3:$AG$3,0)),"") -> 399 | F41: =IFERROR(INDEX(Model_Data!$A$4:$AG$34,MATCH(F$3,Model_Data!$A$4:$A$34,0),MATCH("Expense - Utilities",Model_Data!$A$3:$AG$3,0)),"") -> 299.5 | G41: =IFERROR(INDEX(Model_Data!$A$4:$AG$34,MATCH(G$3,Model_Data!$A$4:$A$34,0),MATCH("Expense - Utilities",Model_Data!$A$3:$AG$3,0)),"") -> 612 | H41: =IFERROR(INDEX(Model_Data!$A$4:$AG$34,MATCH(H$3,Model_Data!$A$4:$A$34,0),MATCH("Expense - Utilities",Model_Data!$A$3:$AG$3,0)),"") -> 183.27 | I41: =IFERROR(INDEX(Model_Data!$A$4:$AG$34,MATCH(I$3,Model_Data!$A$4:$A$34,0),MATCH("Expense - Utilities",Model_Data!$A$3:$AG$3,0)),"") -> 30.45 | J41: =IFERROR(INDEX(Model_Data!$A$4:$AG$34,MATCH(J$3,Model_Data!$A$4:$A$34,0),MATCH("Expense - Utilities",Model_Data!$A$3:$AG$3,0)),"") -> 91.13 | ... AG41: =IFERROR(INDEX(Model_Data!$A$4:$AG$34,MATCH(AG$3,Model_Data!$A$4:$A$34,0),MATCH("Expense - Utilities",Model_Data!$A$3:$AG$3,0)),"") -> 379.37 | AH41: =SUM(C41:AG41) -> 13436.11
A42: Advertising | B42: 6020 | C42: =IFERROR(INDEX(Model_Data!$A$4:$AG$34,MATCH(C$3,Model_Data!$A$4:$A$34,0),MATCH("Expense - Advertising",Model_Data!$A$3:$AG$3,0)),"") -> 0 | D42: =IFERROR(INDEX(Model_Data!$A$4:$AG$34,MATCH(D$3,Model_Data!$A$4:$A$34,0),MATCH("Expense - Advertising",Model_Data!$A$3:$AG$3,0)),"") -> 50 | E42: =IFERROR(INDEX(Model_Data!$A$4:$AG$34,MATCH(E$3,Model_Data!$A$4:$A$34,0),MATCH("Expense - Advertising",Model_Data!$A$3:$AG$3,0)),"") -> 75 | F42: =IFERROR(INDEX(Model_Data!$A$4:$AG$34,MATCH(F$3,Model_Data!$A$4:$A$34,0),MATCH("Expense - Advertising",Model_Data!$A$3:$AG$3,0)),"") -> 112.5 | G42: =IFERROR(INDEX(Model_Data!$A$4:$AG$34,MATCH(G$3,Model_Data!$A$4:$A$34,0),MATCH("Expense - Advertising",Model_Data!$A$3:$AG$3,0)),"") -> 125 | H42: =IFERROR(INDEX(Model_Data!$A$4:$AG$34,MATCH(H$3,Model_Data!$A$4:$A$34,0),MATCH("Expense - Advertising",Model_Data!$A$3:$AG$3,0)),"") -> 150 | I42: =IFERROR(INDEX(Model_Data!$A$4:$AG$34,MATCH(I$3,Model_Data!$A$4:$A$34,0),MATCH("Expense - Advertising",Model_Data!$A$3:$AG$3,0)),"") -> 125 | J42: =IFERROR(INDEX(Model_Data!$A$4:$AG$34,MATCH(J$3,Model_Data!$A$4:$A$34,0),MATCH("Expense - Advertising",Model_Data!$A$3:$AG$3,0)),"") -> 168.75 | ... AG42: =IFERROR(INDEX(Model_Data!$A$4:$AG$34,MATCH(AG$3,Model_Data!$A$4:$A$34,0),MATCH("Expense - Advertising",Model_Data!$A$3:$AG$3,0)),"") -> 0 | AH42: =SUM(C42:AG42) -> 6484.01
A43: Business Tax | B43: 6030 | C43: =IFERROR(INDEX(Model_Data!$A$4:$AG$34,MATCH(C$3,Model_Data!$A$4:$A$34,0),MATCH("Expense - Taxes",Model_Data!$A$3:$AG$3,0)),"") -> 0 | D43: =IFERROR(INDEX(Model_Data!$A$4:$AG$34,MATCH(D$3,Model_Data!$A$4:$A$34,0),MATCH("Expense - Taxes",Model_Data!$A$3:$AG$3,0)),"") -> 0 | E43: =IFERROR(INDEX(Model_Data!$A$4:$AG$34,MATCH(E$3,Model_Data!$A$4:$A$34,0),MATCH("Expense - Taxes",Model_Data!$A$3:$AG$3,0)),"") -> 0 | F43: =IFERROR(INDEX(Model_Data!$A$4:$AG$34,MATCH(F$3,Model_Data!$A$4:$A$34,0),MATCH("Expense - Taxes",Model_Data!$A$3:$AG$3,0)),"") -> 0 | G43: =IFERROR(INDEX(Model_Data!$A$4:$AG$34,MATCH(G$3,Model_Data!$A$4:$A$34,0),MATCH("Expense - Taxes",Model_Data!$A$3:$AG$3,0)),"") -> 57.75 | H43: =IFERROR(INDEX(Model_Data!$A$4:$AG$34,MATCH(H$3,Model_Data!$A$4:$A$34,0),MATCH("Expense - Taxes",Model_Data!$A$3:$AG$3,0)),"") -> 22.5 | I43: =IFERROR(INDEX(Model_Data!$A$4:$AG$34,MATCH(I$3,Model_Data!$A$4:$A$34,0),MATCH("Expense - Taxes",Model_Data!$A$3:$AG$3,0)),"") -> 0 | J43: =IFERROR(INDEX(Model_Data!$A$4:$AG$34,MATCH(J$3,Model_Data!$A$4:$A$34,0),MATCH("Expense - Taxes",Model_Data!$A$3:$AG$3,0)),"") -> 0 | ... AG43: =IFERROR(INDEX(Model_Data!$A$4:$AG$34,MATCH(AG$3,Model_Data!$A$4:$A$34,0),MATCH("Expense - Taxes",Model_Data!$A$3:$AG$3,0)),"") -> 85.28 | AH43: =SUM(C43:AG43) -> 2245.95
A44: Equipment & Supplies | B44: 6040 | C44: =IFERROR(INDEX(Model_Data!$A$4:$AG$34,MATCH(C$3,Model_Data!$A$4:$A$34,0),MATCH("Equipment / Supplies Purchase",Model_Data!$A$3:$AG$3,0)),"") -> 0 | D44: =IFERROR(INDEX(Model_Data!$A$4:$AG$34,MATCH(D$3,Model_Data!$A$4:$A$34,0),MATCH("Equipment / Supplies Purchase",Model_Data!$A$3:$AG$3,0)),"") -> 200 | E44: =IFERROR(INDEX(Model_Data!$A$4:$AG$34,MATCH(E$3,Model_Data!$A$4:$A$34,0),MATCH("Equipment / Supplies Purchase",Model_Data!$A$3:$AG$3,0)),"") -> 0 | F44: =IFERROR(INDEX(Model_Data!$A$4:$AG$34,MATCH(F$3,Model_Data!$A$4:$A$34,0),MATCH("Equipment / Supplies Purchase",Model_Data!$A$3:$AG$3,0)),"") -> 0 | G44: =IFERROR(INDEX(Model_Data!$A$4:$AG$34,MATCH(G$3,Model_Data!$A$4:$A$34,0),MATCH("Equipment / Supplies Purchase",Model_Data!$A$3:$AG$3,0)),"") -> 974.25 | H44: =IFERROR(INDEX(Model_Data!$A$4:$AG$34,MATCH(H$3,Model_Data!$A$4:$A$34,0),MATCH("Equipment / Supplies Purchase",Model_Data!$A$3:$AG$3,0)),"") -> 686.87 | I44: =IFERROR(INDEX(Model_Data!$A$4:$AG$34,MATCH(I$3,Model_Data!$A$4:$A$34,0),MATCH("Equipment / Supplies Purchase",Model_Data!$A$3:$AG$3,0)),"") -> 0 | J44: =IFERROR(INDEX(Model_Data!$A$4:$AG$34,MATCH(J$3,Model_Data!$A$4:$A$34,0),MATCH("Equipment / Supplies Purchase",Model_Data!$A$3:$AG$3,0)),"") -> 0 | ... AG44: =IFERROR(INDEX(Model_Data!$A$4:$AG$34,MATCH(AG$3,Model_Data!$A$4:$A$34,0),MATCH("Equipment / Supplies Purchase",Model_Data!$A$3:$AG$3,0)),"") -> 0 | AH44: =SUM(C44:AG44) -> 5208.23
A45: Other Operating | B45: 6070 | C45: =IFERROR(INDEX(Model_Data!$A$4:$AG$34,MATCH(C$3,Model_Data!$A$4:$A$34,0),MATCH("Expense - Other Operating Expense",Model_Data!$A$3:$AG$3,0)),"") -> 0 | D45: =IFERROR(INDEX(Model_Data!$A$4:$AG$34,MATCH(D$3,Model_Data!$A$4:$A$34,0),MATCH("Expense - Other Operating Expense",Model_Data!$A$3:$AG$3,0)),"") -> 211.25 | E45: =IFERROR(INDEX(Model_Data!$A$4:$AG$34,MATCH(E$3,Model_Data!$A$4:$A$34,0),MATCH("Expense - Other Operating Expense",Model_Data!$A$3:$AG$3,0)),"") -> 117.12 | F45: =IFERROR(INDEX(Model_Data!$A$4:$AG$34,MATCH(F$3,Model_Data!$A$4:$A$34,0),MATCH("Expense - Other Operating Expense",Model_Data!$A$3:$AG$3,0)),"") -> 199.75 | G45: =IFERROR(INDEX(Model_Data!$A$4:$AG$34,MATCH(G$3,Model_Data!$A$4:$A$34,0),MATCH("Expense - Other Operating Expense",Model_Data!$A$3:$AG$3,0)),"") -> 98.75 | H45: =IFERROR(INDEX(Model_Data!$A$4:$AG$34,MATCH(H$3,Model_Data!$A$4:$A$34,0),MATCH("Expense - Other Operating Expense",Model_Data!$A$3:$AG$3,0)),"") -> 461.12 | I45: =IFERROR(INDEX(Model_Data!$A$4:$AG$34,MATCH(I$3,Model_Data!$A$4:$A$34,0),MATCH("Expense - Other Operating Expense",Model_Data!$A$3:$AG$3,0)),"") -> 41.37 | J45: =IFERROR(INDEX(Model_Data!$A$4:$AG$34,MATCH(J$3,Model_Data!$A$4:$A$34,0),MATCH("Expense - Other Operating Expense",Model_Data!$A$3:$AG$3,0)),"") -> 0 | ... AG45: =IFERROR(INDEX(Model_Data!$A$4:$AG$34,MATCH(AG$3,Model_Data!$A$4:$A$34,0),MATCH("Expense - Other Operating Expense",Model_Data!$A$3:$AG$3,0)),"") -> 0 | AH45: =SUM(C45:AG45) -> 6461.81
A46: Total Operating Expenses | C46: =SUM(C40:C45) -> 562.6 | D46: =SUM(D40:D45) -> 3938.52 | E46: =SUM(E40:E45) -> 3391.12 | F46: =SUM(F40:F45) -> 3411.75 | G46: =SUM(G40:G45) -> 4667.75 | H46: =SUM(H40:H45) -> 2905.14 | I46: =SUM(I40:I45) -> 1598.2 | J46: =SUM(J40:J45) -> 3059.88 | ... AH46: =SUM(AH40:AH45) -> 144065.62
...

Sheet Annual_KPIs
A1: Claire Studio — Annual Summary & KPIs
A2: Amounts shown in $ | Source: Cleaned cash-ledger transaction records via Monthly P&L | 2019=2mo | 2020=10mo | 2021=12mo | 2022=7mo (through July)
B4: 2019 | C4: 2020 | D4: 2021 | E4: 2022 | F4: Notes / Context
A5: Revenue Summary
A6: Months of operation | B6: =COUNTIF('Monthly_P&L'!$C$4:$AG$4,B$4) -> 2 | C6: =COUNTIF('Monthly_P&L'!$C$4:$AG$4,C$4) -> 10 | D6: =COUNTIF('Monthly_P&L'!$C$4:$AG$4,D$4) -> 12 | E6: =COUNTIF('Monthly_P&L'!$C$4:$AG$4,E$4) -> 7 | F6: 2019: Nov–Dec | 2020: Apr–May excluded (COVID) | 2022: Jan–Jul
A7: Choreography | B7: =SUMIFS('Monthly_P&L'!$C$7:$AG$7,'Monthly_P&L'!$C$4:$AG$4,B$4) -> 3250 | C7: =SUMIFS('Monthly_P&L'!$C$7:$AG$7,'Monthly_P&L'!$C$4:$AG$4,C$4) -> 38162.5 | D7: =SUMIFS('Monthly_P&L'!$C$7:$AG$7,'Monthly_P&L'!$C$4:$AG$4,D$4) -> 62811.87 | E7: =SUMIFS('Monthly_P&L'!$C$7:$AG$7,'Monthly_P&L'!$C$4:$AG$4,E$4) -> 36581.75 | F7: Core program throughout
A8: Fitness | B8: =SUMIFS('Monthly_P&L'!$C$8:$AG$8,'Monthly_P&L'!$C$4:$AG$4,B$4) -> 0 | C8: =SUMIFS('Monthly_P&L'!$C$8:$AG$8,'Monthly_P&L'!$C$4:$AG$4,C$4) -> 13956.25 | D8: =SUMIFS('Monthly_P&L'!$C$8:$AG$8,'Monthly_P&L'!$C$4:$AG$4,D$4) -> 16656.25 | E8: =SUMIFS('Monthly_P&L'!$C$8:$AG$8,'Monthly_P&L'!$C$4:$AG$4,E$4) -> 7312.5 | F8: Owner = instructor, zero labor cost
A9: Karate | B9: =SUMIFS('Monthly_P&L'!$C$9:$AG$9,'Monthly_P&L'!$C$4:$AG$4,B$4) -> 0 | C9: =SUMIFS('Monthly_P&L'!$C$9:$AG$9,'Monthly_P&L'!$C$4:$AG$4,C$4) -> 7000 | D9: =SUMIFS('Monthly_P&L'!$C$9:$AG$9,'Monthly_P&L'!$C$4:$AG$4,D$4) -> 30531.25 | E9: =SUMIFS('Monthly_P&L'!$C$9:$AG$9,'Monthly_P&L'!$C$4:$AG$4,E$4) -> 20887.5 | F9: Launched Sep 2020. Revenue share with Karate Instructor
A10: Gymnastics | B10: =SUMIFS('Monthly_P&L'!$C$10:$AG$10,'Monthly_P&L'!$C$4:$AG$4,B$4) -> 1200 | C10: =SUMIFS('Monthly_P&L'!$C$10:$AG$10,'Monthly_P&L'!$C$4:$AG$4,C$4) -> 6618.75 | D10: =SUMIFS('Monthly_P&L'!$C$10:$AG$10,'Monthly_P&L'!$C$4:$AG$4,D$4) -> 0 | E10: =SUMIFS('Monthly_P&L'!$C$10:$AG$10,'Monthly_P&L'!$C$4:$AG$4,E$4) -> 0 | F10: Early program. Discontinued after COVID
A11: Hall Rental | B11: =SUMIFS('Monthly_P&L'!$C$20:$AG$20,'Monthly_P&L'!$C$4:$AG$4,B$4) -> 0 | C11: =SUMIFS('Monthly_P&L'!$C$20:$AG$20,'Monthly_P&L'!$C$4:$AG$4,C$4) -> 0 | D11: =SUMIFS('Monthly_P&L'!$C$20:$AG$20,'Monthly_P&L'!$C$4:$AG$4,D$4) -> 5829.12 | E11: =SUMIFS('Monthly_P&L'!$C$20:$AG$20,'Monthly_P&L'!$C$4:$AG$4,E$4) -> 14337.5 | F11: Hall 2 subrental from early 2021
A12: Ballet Shoes | B12: =SUMIFS('Monthly_P&L'!$C$14:$AG$14,'Monthly_P&L'!$C$4:$AG$4,B$4) -> 0 | C12: =SUMIFS('Monthly_P&L'!$C$14:$AG$14,'Monthly_P&L'!$C$4:$AG$4,C$4) -> 568.75 | D12: =SUMIFS('Monthly_P&L'!$C$14:$AG$14,'Monthly_P&L'!$C$4:$AG$4,D$4) -> 926.25 | E12: =SUMIFS('Monthly_P&L'!$C$14:$AG$14,'Monthly_P&L'!$C$4:$AG$4,E$4) -> 156.25 | F12: Inventory resale. 54 pairs. Cost range based on source records
A13: Gymnastic Suits | B13: =SUMIFS('Monthly_P&L'!$C$15:$AG$15,'Monthly_P&L'!$C$4:$AG$4,B$4) -> 0 | C13: =SUMIFS('Monthly_P&L'!$C$15:$AG$15,'Monthly_P&L'!$C$4:$AG$4,C$4) -> 2075 | D13: =SUMIFS('Monthly_P&L'!$C$15:$AG$15,'Monthly_P&L'!$C$4:$AG$4,D$4) -> 2068.75 | E13: =SUMIFS('Monthly_P&L'!$C$15:$AG$15,'Monthly_P&L'!$C$4:$AG$4,E$4) -> 425 | F13: 53 suits. Owner sewed (2020), tailor from Dec 2020
A14: Events & Photos | B14: =SUMIFS('Monthly_P&L'!$C$22:$AG$22,'Monthly_P&L'!$C$4:$AG$4,B$4) -> 0 | C14: =SUMIFS('Monthly_P&L'!$C$22:$AG$22,'Monthly_P&L'!$C$4:$AG$4,C$4) -> 0 | D14: =SUMIFS('Monthly_P&L'!$C$22:$AG$22,'Monthly_P&L'!$C$4:$AG$4,D$4) -> 878.11 | E14: =SUMIFS('Monthly_P&L'!$C$22:$AG$22,'Monthly_P&L'!$C$4:$AG$4,E$4) -> 612.63 | F14: Competition entry fees, performance photos
A15: Other Revenue | B15: =SUMIFS('Monthly_P&L'!$C$23:$AG$23,'Monthly_P&L'!$C$4:$AG$4,B$4) -> 125 | C15: =SUMIFS('Monthly_P&L'!$C$23:$AG$23,'Monthly_P&L'!$C$4:$AG$4,C$4) -> 856.25 | D15: =SUMIFS('Monthly_P&L'!$C$23:$AG$23,'Monthly_P&L'!$C$4:$AG$4,D$4) -> 1190.5 | E15: =SUMIFS('Monthly_P&L'!$C$23:$AG$23,'Monthly_P&L'!$C$4:$AG$4,E$4) -> 125
A16: TOTAL REVENUE | B16: =SUMIFS('Monthly_P&L'!$C$26:$AG$26,'Monthly_P&L'!$C$4:$AG$4,B$4) -> 4575 | C16: =SUMIFS('Monthly_P&L'!$C$26:$AG$26,'Monthly_P&L'!$C$4:$AG$4,C$4) -> 69237.5 | D16: =SUMIFS('Monthly_P&L'!$C$26:$AG$26,'Monthly_P&L'!$C$4:$AG$4,D$4) -> 120892.1 | E16: =SUMIFS('Monthly_P&L'!$C$26:$AG$26,'Monthly_P&L'!$C$4:$AG$4,E$4) -> 80631.88 | F16: FY2021 peak full year; 2022 is partial through July.
A18: Cost of Goods Sold
A19: Ballet Shoes COGS | B19: =SUMIFS('Monthly_P&L'!$C$29:$AG$29,'Monthly_P&L'!$C$4:$AG$4,B$4) -> 0 | C19: =SUMIFS('Monthly_P&L'!$C$29:$AG$29,'Monthly_P&L'!$C$4:$AG$4,C$4) -> 371.55 | D19: =SUMIFS('Monthly_P&L'!$C$29:$AG$29,'Monthly_P&L'!$C$4:$AG$4,D$4) -> 605.12 | E19: =SUMIFS('Monthly_P&L'!$C$29:$AG$29,'Monthly_P&L'!$C$4:$AG$4,E$4) -> 102.08 | F19: Weighted-average estimated COGS from item-level purchase history; total ballet shoe cost $1,078.75.
A20: Gymnastic Suit COGS | B20: =SUMIFS('Monthly_P&L'!$C$30:$AG$30,'Monthly_P&L'!$C$4:$AG$4,B$4) -> 0 | C20: =SUMIFS('Monthly_P&L'!$C$30:$AG$30,'Monthly_P&L'!$C$4:$AG$4,C$4) -> 1559.38 | D20: =SUMIFS('Monthly_P&L'!$C$30:$AG$30,'Monthly_P&L'!$C$4:$AG$4,D$4) -> 1275 | E20: =SUMIFS('Monthly_P&L'!$C$30:$AG$30,'Monthly_P&L'!$C$4:$AG$4,E$4) -> 300 | F20: Fabric/tailor/chevron/thread costs captured in clean ledger.
A21: TOTAL COGS | B21: =SUMIFS('Monthly_P&L'!$C$31:$AG$31,'Monthly_P&L'!$C$4:$AG$4,B$4) -> 0 | C21: =SUMIFS('Monthly_P&L'!$C$31:$AG$31,'Monthly_P&L'!$C$4:$AG$4,C$4) -> 1930.93 | D21: =SUMIFS('Monthly_P&L'!$C$31:$AG$31,'Monthly_P&L'!$C$4:$AG$4,D$4) -> 1880.12 | E21: =SUMIFS('Monthly_P&L'!$C$31:$AG$31,'Monthly_P&L'!$C$4:$AG$4,E$4) -> 402.08 | F21: COGS shown separately for resale/inventory items.
A23: Operating Expenses
A24: Payroll | B24: =SUMIFS('Monthly_P&L'!$C$34:$AG$34,'Monthly_P&L'!$C$4:$AG$4,B$4) -> 0 | C24: =SUMIFS('Monthly_P&L'!$C$34:$AG$34,'Monthly_P&L'!$C$4:$AG$4,C$4) -> 8792.5 | D24: =SUMIFS('Monthly_P&L'!$C$34:$AG$34,'Monthly_P&L'!$C$4:$AG$4,D$4) -> 19335.63 | E24: =SUMIFS('Monthly_P&L'!$C$34:$AG$34,'Monthly_P&L'!$C$4:$AG$4,E$4) -> 12967.49 | F24: Co-Founder $750/mo fixed + Karate Instructor rev share (40%→50%) + substitutes
A25: Rent | B25: =SUMIFS('Monthly_P&L'!$C$40:$AG$40,'Monthly_P&L'!$C$4:$AG$4,B$4) -> 2775 | C25: =SUMIFS('Monthly_P&L'!$C$40:$AG$40,'Monthly_P&L'!$C$4:$AG$4,C$4) -> 25202.76 | D25: =SUMIFS('Monthly_P&L'!$C$40:$AG$40,'Monthly_P&L'!$C$4:$AG$4,D$4) -> 53421.75 | E25: =SUMIFS('Monthly_P&L'!$C$40:$AG$40,'Monthly_P&L'!$C$4:$AG$4,E$4) -> 28830 | F25: Increased with Hall 2 expansion in early 2021
A26: Utilities | B26: =SUMIFS('Monthly_P&L'!$C$41:$AG$41,'Monthly_P&L'!$C$4:$AG$4,B$4) -> 1264.87 | C26: =SUMIFS('Monthly_P&L'!$C$41:$AG$41,'Monthly_P&L'!$C$4:$AG$4,C$4) -> 2159.17 | D26: =SUMIFS('Monthly_P&L'!$C$41:$AG$41,'Monthly_P&L'!$C$4:$AG$4,D$4) -> 5837.26 | E26: =SUMIFS('Monthly_P&L'!$C$41:$AG$41,'Monthly_P&L'!$C$4:$AG$4,E$4) -> 4174.81
A27: Advertising | B27: =SUMIFS('Monthly_P&L'!$C$42:$AG$42,'Monthly_P&L'!$C$4:$AG$4,B$4) -> 50 | C27: =SUMIFS('Monthly_P&L'!$C$42:$AG$42,'Monthly_P&L'!$C$4:$AG$4,C$4) -> 2320.01 | D27: =SUMIFS('Monthly_P&L'!$C$42:$AG$42,'Monthly_P&L'!$C$4:$AG$4,D$4) -> 3110.75 | E27: =SUMIFS('Monthly_P&L'!$C$42:$AG$42,'Monthly_P&L'!$C$4:$AG$4,E$4) -> 1003.25 | F27: Local print + Facebook. Consistently low
A28: Business Tax | B28: =SUMIFS('Monthly_P&L'!$C$43:$AG$43,'Monthly_P&L'!$C$4:$AG$4,B$4) -> 0 | C28: =SUMIFS('Monthly_P&L'!$C$43:$AG$43,'Monthly_P&L'!$C$4:$AG$4,C$4) -> 204.75 | D28: =SUMIFS('Monthly_P&L'!$C$43:$AG$43,'Monthly_P&L'!$C$4:$AG$4,D$4) -> 1132.86 | E28: =SUMIFS('Monthly_P&L'!$C$43:$AG$43,'Monthly_P&L'!$C$4:$AG$4,E$4) -> 908.34 | F28: Simplified tax. 2020 waived under COVID relief
A29: Class Supplies & Events | B29: =SUMIFS('Monthly_P&L'!$C$35:$AG$35,'Monthly_P&L'!$C$4:$AG$4,B$4)+SUMIFS('Monthly_P&L'!$C$36:$AG$36,'Monthly_P&L'!$C$4:$AG$4,B$4) -> 0 | C29: =SUMIFS('Monthly_P&L'!$C$35:$AG$35,'Monthly_P&L'!$C$4:$AG$4,C$4)+SUMIFS('Monthly_P&L'!$C$36:$AG$36,'Monthly_P&L'!$C$4:$AG$4,C$4) -> 268.75 | D29: =SUMIFS('Monthly_P&L'!$C$35:$AG$35,'Monthly_P&L'!$C$4:$AG$4,D$4)+SUMIFS('Monthly_P&L'!$C$36:$AG$36,'Monthly_P&L'!$C$4:$AG$4,D$4) -> 603.5 | E29: =SUMIFS('Monthly_P&L'!$C$35:$AG$35,'Monthly_P&L'!$C$4:$AG$4,E$4)+SUMIFS('Monthly_P&L'!$C$36:$AG$36,'Monthly_P&L'!$C$4:$AG$4,E$4) -> 100 | F29: Class materials plus competition/event costs
A30: Equipment & Supplies | B30: =SUMIFS('Monthly_P&L'!$C$44:$AG$44,'Monthly_P&L'!$C$4:$AG$4,B$4) -> 200 | C30: =SUMIFS('Monthly_P&L'!$C$44:$AG$44,'Monthly_P&L'!$C$4:$AG$4,C$4) -> 4058.61 | D30: =SUMIFS('Monthly_P&L'!$C$44:$AG$44,'Monthly_P&L'!$C$4:$AG$4,D$4) -> 917.74 | E30: =SUMIFS('Monthly_P&L'!$C$44:$AG$44,'Monthly_P&L'!$C$4:$AG$4,E$4) -> 31.88
A31: Other Operating | B31: =SUMIFS('Monthly_P&L'!$C$45:$AG$45,'Monthly_P&L'!$C$4:$AG$4,B$4) -> 211.25 | C31: =SUMIFS('Monthly_P&L'!$C$45:$AG$45,'Monthly_P&L'!$C$4:$AG$4,C$4) -> 1710.49 | D31: =SUMIFS('Monthly_P&L'!$C$45:$AG$45,'Monthly_P&L'!$C$4:$AG$4,D$4) -> 2584 | E31: =SUMIFS('Monthly_P&L'!$C$45:$AG$45,'Monthly_P&L'!$C$4:$AG$4,E$4) -> 1956.07
A32: TOTAL EXPENSES | B32: =SUMIFS('Monthly_P&L'!$C$31:$AG$31,'Monthly_P&L'!$C$4:$AG$4,B$4)+SUMIFS('Monthly_P&L'!$C$37:$AG$37,'Monthly_P&L'!$C$4:$AG$4,B$4)+SUMIFS('Monthly_P&L'!$C$46:$AG$46,'Monthly_P&L'!$C$4:$AG$4,B$4) -> 4501.12 | C32: =SUMIFS('Monthly_P&L'!$C$31:$AG$31,'Monthly_P&L'!$C$4:$AG$4,C$4)+SUMIFS('Monthly_P&L'!$C$37:$AG$37,'Monthly_P&L'!$C$4:$AG$4,C$4)+SUMIFS('Monthly_P&L'!$C$46:$AG$46,'Monthly_P&L'!$C$4:$AG$4,C$4) -> 46647.97 | D32: =SUMIFS('Monthly_P&L'!$C$31:$AG$31,'Monthly_P&L'!$C$4:$AG$4,D$4)+SUMIFS('Monthly_P&L'!$C$37:$AG$37,'Monthly_P&L'!$C$4:$AG$4,D$4)+SUMIFS('Monthly_P&L'!$C$46:$AG$46,'Monthly_P&L'!$C$4:$AG$4,D$4) -> 88823.61 | E32: =SUMIFS('Monthly_P&L'!$C$31:$AG$31,'Monthly_P&L'!$C$4:$AG$4,E$4)+SUMIFS('Monthly_P&L'!$C$37:$AG$37,'Monthly_P&L'!$C$4:$AG$4,E$4)+SUMIFS('Monthly_P&L'!$C$46:$AG$46,'Monthly_P&L'!$C$4:$AG$4,E$4) -> 50373.92
A34: Profitability
A35: NET OPERATING INCOME | B35: =SUMIFS('Monthly_P&L'!$C$48:$AG$48,'Monthly_P&L'!$C$4:$AG$4,B$4) -> 73.88 | C35: =SUMIFS('Monthly_P&L'!$C$48:$AG$48,'Monthly_P&L'!$C$4:$AG$4,C$4) -> 22589.53 | D35: =SUMIFS('Monthly_P&L'!$C$48:$AG$48,'Monthly_P&L'!$C$4:$AG$4,D$4) -> 32068.49 | E35: =SUMIFS('Monthly_P&L'!$C$48:$AG$48,'Monthly_P&L'!$C$4:$AG$4,E$4) -> 30257.96 | F35: Revenue minus all operating expenses, COGS, and service costs
