Workbook
Name LaborPct: ANALYSIS!$B$27:$B$27
Name MaterialPct: ANALYSIS!$B$28:$B$28
Name MobilityData: Data!$B$5:$C$16
Name OverheadPct: ANALYSIS!$B$29:$B$29

Sheet README
B1: SIEMENS MOBILITY — FINANCIAL ANALYSIS MODEL
B3: WHAT THIS FILE IS
B4: This model analyzes Siemens Mobility segment performance using real data from the FY2025 Annual Report. It includes a variance analysis explaining profit movement from FY2024 to FY2025, a labor cost model, a 12-month FY2026 forecast, and an executive dashboard. Independent financial analysis built from the publicly available Siemens FY2025 Annual Report. Not affiliated with or endorsed by Siemens.
B6: How to navigate
B7: README — Start here. You are reading it.
B8: DATA — All source numbers from Siemens FY2025 Annual Report. Change inputs here only.
B9: ANALYSIS — Variance bridge showing why profit changed + labor cost center model.
B10: FORECAST — Monthly FY2026 projection based on EUR 12B backlog conversion target.
B11: DASHBOARD — One page executive view with charts and KPI cards.
B12: SOURCES — Every data point documented with note references.
B14: KEY ASSUMPTIONS
B15: 1. Labor ratio of 44% derived from Group personnel costs Note 27 — actual plant data from SAP replaces this on day one.
... B18: Data as of September 30 2025 | Source: Siemens FY2025 Annual Report | Built: April 2026

Sheet Data
A1: SIEMENS MOBILITY — FY2025 FINANCIAL DATA
A2: Source: Siemens FY2025 Annual Report
A4: Metric | B4: FY2024 Actual | C4: FY2025 Actual | D4: Unit | E4: Notes
A5: Revenue | B5: 11420 | C5: 12444 | D5: €M | E5: Segment revenue
A6: Profit | B6: 1013 | C6: 1099 | D6: €M | E6: EBITA adjusted
A7: Profit Margin | B7: =B6/B5 -> 0.088704028 | C7: =C6/C5 -> 0.088315654 | D7: % | E7: Calculated
A8: Orders | B8: 15795 | C8: 16994 | D8: €M | E8: New contracts signed
A9: Severance | B9: 25 | C9: 32 | D9: €M | E9: One-time restructuring cost
A10: Order Backlog | B10: 48000 | C10: 52000 | D10: €M | E10: Total unbuilt orders
A11: Backlog FY2026 Conversion | B11: 0 | C11: 12000 | D11: €M | E11: Expected next year revenue
A12: CAPEX | B12: 190 | C12: 222 | D12: €M | E12: PP&E additions
A13: Depreciation | B13: 256 | C13: 270 | D13: €M | E13: Asset aging
A14: FCF | B14: 1159 | C14: 1027 | D14: €M | E14: Cash after capex
A15: Margin Target Low | B15: 0.1 | C15: 0.1 | D15: % | E15: Siemens stated range
A16: Margin Target High | B16: 0.13 | C16: 0.13 | D16: % | E16: Siemens stated range
A18: DERIVED METRICS
A19: Revenue Growth | C19: =(C5-B5)/B5 -> 0.08966725
A20: Profit Growth | C20: =(C6-B6)/B6 -> 0.084896347 | E20: % change in profit
A21: Margin Change (pp) | C21: =C7-B7 -> -0.00038837389 | E21: Percentage point difference Report shows -0.1pp due to rounding. Model uses full precision.
A22: CAPEX/Depreciation Ratio | B22: =B12/B13 -> 0.7421875 | C22: =C12/C13 -> 0.82222222
A23: FCF Change | C23: =(C14-B14)/B14 -> -0.11389129 | E23: % change in FCF
A24: Backlog Coverage (years) | C24: =C10/C5 -> 4.1787207 | E24: How many years of revenue in backlog

Sheet ANALYSIS
A1: SIEMENS MOBILITY — VARIANCE BRIDGE FY2024 → FY2025
A2: Profit Movement Analysis
A4: Component | B4: Formula Logic | C4: €M Impact | D4: Explanation
A5: FY2024 Baseline Profit | B5: Direct reference from DATA sheet | C5: =Data!B6 -> 1013 | D5: Starting point
A6: Volume effect | B6: (FY2025 Revenue - FY2024 Revenue) × FY2024 Margin | C6: =(Data!C5-Data!B5)*Data!B7 -> 90.832925 | D6: Extra profit from selling more
A7: Margin/Cost Effect | B7: (FY2025 Margin - FY2024 Margin) × FY2025 Revenue | C7: =(Data!C7-Data!B7)*Data!C5 -> -4.8329247 | D7: Impact of margin compression
A8: Severance Change | B8: -(FY2025 Severance - FY2024 Severance) | C8: =-(Data!C9-Data!B9) -> -7 | D8: Incremental restructuring cost
A9: Residual / Other | B9: FY2025 Actual - Sum of explained components | C9: =Data!C6-SUM(ANALYSIS!C5:C8) -> 7 | D9: Unexplained difference
A11: FY2025 Implied Profit | B11: SUM of all bridge components above | C11: =SUM(C5:C9) -> 1099 | D11: Model result — must equal FY2025 actual
A12: FY2025 Actual Profit | B12: Direct reference from DATA sheet | C12: =Data!C6 -> 1099 | D12: From annual report
A13: Variance (must = 0) | B13: Implied minus Actual — must equal zero | C13: =C11-C12 -> 0 | D13: Model check
A15: KEY RATIOS & SIGNALS
A16: CAPEX Health Ratio | B16: CAPEX divided by Depreciation | C16: =Data!C12/Data!C13 -> 0.82222222 | D16: =IF(C16>=1, "Healthy - Investing ahead of aging", "Caution - assets aging faster than investment") -> Caution - assets aging faster than investment
A17: FCF Conversion Rate | B17: FCF divided by Profit | C17: =Data!C14/Data!C6 -> 0.9344859 | D17: =IF(C17>=0.8,"Strong cash conversion","Cash conversion below target — review timing") -> Strong cash conversion
A18: Margin vs Target Low | B18: Actual Margin minus Minimum Target (10%) | C18: =Data!C7-Data!C15 -> -0.011684346 | D18: =IF(C18>=0, "At or above minimum target", "Below minimum target by "&TEXT(ABS(C18),"0.00%")) -> Below minimum target by 1.17%
A19: Margin vs Target High | B19: Actual Margin minus Maximum Target (13%) | C19: =Data!C7-Data!C16 -> -0.041684346 | D19: =IF(C19>=0,"At or above maximum target","Gap to maximum target: "&TEXT(ABS(C19),"0.00%")) -> Gap to maximum target: 4.17%
A20: Revenue per Backlog Year | B20: Direct reference — FY2025 Revenue | C20: =Data!C10/Data!C5 -> 4.1787207 | D20: ="At current revenue pace, backlog clears in "&TEXT(Data!C10/Data!C5,"0.0")&" years" -> At current revenue pace, backlog clears in 4.2 years
A23: LABOR & COST CENTER ANALYSIS
A24: Cost structure derived from Siemens FY2025 Annual Report — Note 27 and Consolidated P&L
A25: Labor ratio based on Group personnel costs €31,598M ÷ Group revenue €78,914M = 40% of revenue = 44% of total costs
A26: Assumptions | B26: Ratio | C26: Source
A27: Labor % of Total Costs | B27: 0.44 | C27: Note 27, Siemens FY2025 Annual Report
A28: Materials % of Total Costs | B28: 0.36 | C28: Derived — remainder after labor and overhead
A29: Overhead % of Total Costs | B29: 0.2 | C29: Industry standard, consistent with capital-intensive manufacturing
A30: Verify (must = 100%) | B30: =SUM(B27:B29) -> 1 | C30: Sanity check — must be green
A32: COST STRUCTURE DERIVATION
A33: Total Revenue | B33: Direct from DATA sheet | C33: =Data!C5 -> 12444 | D33: FY2025 actual €12,444M
A34: Total Profit | B34: Direct from DATA sheet | C34: =Data!C6 -> 1099 | D34: FY2025 actual €1,099M
A35: Total Costs | B35: Revenue minus Profit | C35: =C33-C34 -> 11345 | D35: Implied total cost base
A36: Costs as % of Revenue | B36: Total Costs divided by Revenue | C36: =C35/C33 -> 0.91168435 | D36: Cost ratio — higher means worse
A38: PART A — LABOR BOOKING MODEL
A39: Monthly simulation based on FY2025 Mobility segment figures
A40: Labor Category | B40: Annual Estimate €M | C40: Monthly Budget €M | D40: Monthly Actual €M | E40: Variance €M | F40: Variance % | G40: Status
A41: Direct Labor | B41: {=C35 * LaborPct * 0.7} -> 3494.26 | C41: =B41/12 -> 291.18833 | D41: =C41*1.03 -> 299.92398 | E41: =C41-D41 -> -8.73565 | F41: =E41/C41 -> -0.03 | G41: =IF(F41>=0, "Favorable",IF(F41>=-0.05, "Watch", "Unfavorable - Action Required")) -> Watch
A42: Indirect Labor | B42: {=C35*LaborPct*0.3} -> 1497.54 | C42: =B42/12 -> 124.795 | D42: =C42*0.98 -> 122.2991 | E42: =C42-D42 -> 2.4959 | F42: =E42/C42 -> 0.02 | G42: =IF(F42>=0, "Favorable",IF(F42>=-0.05, "Watch", "Unfavorable - Action Required")) -> Favorable
A43: Materials | B43: {=C35*MaterialPct} -> 4084.2 | C43: =B43/12 -> 340.35 | D43: =C43*1.05 -> 357.3675 | E43: =C43-D43 -> -17.0175 | F43: =E43/C43 -> -0.05 | G43: =IF(F43>=0, "Favorable",IF(F43>=-0.05, "Watch", "Unfavorable - Action Required")) -> Unfavorable - Action Required
A44: Manufacturing Overhead | B44: =C35*B29 -> 2269 | C44: =B44/12 -> 189.08333 | D44: =C44*1.01 -> 190.97417 | E44: =C44-D44 -> -1.8908333 | F44: =E44/C44 -> -0.01 | G44: =IF(F44>=0, "Favorable",IF(F44>=-0.05, "Watch", "Unfavorable - Action Required")) -> Watch
A45: TOTAL | B45: =SUM(B41:B44) -> 11345 | C45: =B45/12 -> 945.41667 | D45: =SUM(D41:D44) -> 970.56475 | E45: =C45-D45 -> -25.148083 | F45: =E45/C45 -> -0.0266 | G45: =IF(F45>=0,"Total: Favorable",IF(F45>=-0.03,"Total: Watch - Review Line Items","Total: Unfavorable - Immediate Review")) -> Total: Watch - Review Line Items
A47: PART B — COST CENTER CONTROL SUMMARY
A48: Management view — monthly performance vs budget
...

Sheet FORECAST
A1: SIEMENS MOBILITY — FY2026 FORECAST MODEL
A2: Based on €12B backlog conversion target — Siemens FY2025 Annual Report
A4: FORECAST ASSUMPTIONS
A5: Annual Revenue Target | B5: =Data!C11 -> 12000 | C5: Pulled from backlog conversion
A6: Margin Scenario — Low | B6: =Data!C15 -> 0.1 | C6: Siemens minimum target 10%
A7: Margin Scenario — High | B7: =Data!C16 -> 0.13 | C7: Siemens maximum target 13%
A8: Margin Scenario — Base | B8: =(B6+B7)/2 -> 0.115 | C8: Midpoint of target range
A9: FY2025 Actual Margin | B9: =Data!C7 -> 0.088315654 | C9: Reference point — current performance
A10: Annual Cost Target (Base) | B10: =B5*(1-B8) -> 10620 | C10: Revenue minus expected profit
A11: Monthly Revenue Baseline | B11: =B5/12 -> 1000 | C11: Flat baseline before seasonality
A12: Margin Gap to Close | B12: =B8-B9 -> 0.026684346 | C12: How much margin must improve vs FY2025
A14: SEASONALITY WEIGHTS
A15: Weights must sum to 100% — sanity check built in
A16: Month | B16: Weight | C16: Rationale | D16: Monthly Revenue €M
A17: October | B17: 0.08 | C17: Fiscal year start — ramp up | D17: =B17*$B$5 -> 960
A18: November | B18: 0.085 | C18: Full production | D18: =B18*$B$5 -> 1020
A19: December | B19: 0.07 | C19: Holiday slowdown | D19: =B19*$B$5 -> 840
A20: January | B20: 0.075 | C20: Restart after holidays | D20: =B20*$B$5 -> 900
A21: February | B21: 0.09 | C21: Full production | D21: =B21*$B$5 -> 1080
A22: March | B22: 0.095 | C22: Q1 close push | D22: =B22*$B$5 -> 1140
A23: April | B23: 0.085 | C23: Full production | D23: =B23*$B$5 -> 1020
A24: May | B24: 0.09 | C24: Full production | D24: =B24*$B$5 -> 1080
A25: June | B25: 0.08 | C25: Pre-summer push | D25: =B25*$B$5 -> 960
A26: July | B26: 0.07 | C26: Summer vacation — reduced output | D26: =B26*$B$5 -> 840
A27: August | B27: 0.08 | C27: Ramp back up | D27: =B27*$B$5 -> 960
A28: September | B28: 0.1 | C28: Fiscal year-end — maximum push | D28: =B28*$B$5 -> 1200
A29: Total | B29: =SUM(B17:B28) -> 1 | C29: Must equal 100% | D29: =SUM(D17:D28) -> 12000
A31: MONTHLY FORECAST — FY2026
A32: Month | B32: Revenue €M | C32: Target Margin % | D32: Target Profit €M | E32: Target Costs €M | F32: Cumulative Revenue €M | G32: Cumulative Profit €M | H32: % of Annual Target | I32: On Track?
A33: October | B33: =D17 -> 960 | C33: =($B$9+($B$8-$B$9)*(ROW()-33)/11) -> 0.088315654 | D33: =B33*C33 -> 84.783028 | E33: =B33-D33 -> 875.21697 | F33: =B33 -> 960 | G33: =D33 -> 84.783028 | H33: =F33/$B$5 -> 0.08 | I33: =IF(H33>=(ROW()-33+1)/12+0.02,"Ahead of Plan",IF(H33>=(ROW()-33+1)/12-0.02,"On Track","Behind Plan - Review Required")) -> On Track
A34: November | B34: =D18 -> 1020 | C34: =($B$9+($B$8-$B$9)*(ROW()-33)/11) -> 0.090741504 | D34: =B34*C34 -> 92.556334 | E34: =B34-D34 -> 927.44367 | F34: =F33+B34 -> 1980 | G34: =G33+D34 -> 177.33936 | H34: =F34/$B$5 -> 0.165 | I34: =IF(H34>=(ROW()-33+1)/12+0.02,"Ahead of Plan",IF(H34>=(ROW()-33+1)/12-0.02,"On Track","Behind Plan - Review Required")) -> On Track
A35: December | B35: =D19 -> 840 | C35: =($B$9+($B$8-$B$9)*(ROW()-33)/11) -> 0.093167353 | D35: =B35*C35 -> 78.260577 | E35: =B35-D35 -> 761.73942 | F35: =F34+B35 -> 2820 | G35: =G34+D35 -> 255.59994 | H35: =F35/$B$5 -> 0.235 | I35: =IF(H35>=(ROW()-33+1)/12+0.02,"Ahead of Plan",IF(H35>=(ROW()-33+1)/12-0.02,"On Track","Behind Plan - Review Required")) -> On Track
A36: January | B36: =D20 -> 900 | C36: =($B$9+($B$8-$B$9)*(ROW()-33)/11) -> 0.095593203 | D36: =B36*C36 -> 86.033883 | E36: =B36-D36 -> 813.96612 | F36: =F35+B36 -> 3720 | G36: =G35+D36 -> 341.63382 | H36: =F36/$B$5 -> 0.31 | I36: =IF(H36>=(ROW()-33+1)/12+0.02,"Ahead of Plan",IF(H36>=(ROW()-33+1)/12-0.02,"On Track","Behind Plan - Review Required")) -> Behind Plan - Review Required
A37: February | B37: =D21 -> 1080 | C37: =($B$9+($B$8-$B$9)*(ROW()-33)/11) -> 0.098019053 | D37: =B37*C37 -> 105.86058 | E37: =B37-D37 -> 974.13942 | F37: =F36+B37 -> 4800 | G37: =G36+D37 -> 447.4944 | H37: =F37/$B$5 -> 0.4 | I37: =IF(H37>=(ROW()-33+1)/12+0.02,"Ahead of Plan",IF(H37>=(ROW()-33+1)/12-0.02,"On Track","Behind Plan - Review Required")) -> On Track
A38: March | B38: =D22 -> 1140 | C38: =($B$9+($B$8-$B$9)*(ROW()-33)/11) -> 0.1004449 | D38: =B38*C38 -> 114.50719 | E38: =B38-D38 -> 1025.4928 | F38: =F37+B38 -> 5940 | G38: =G37+D38 -> 562.00159 | H38: =F38/$B$5 -> 0.495 | I38: =IF(H38>=(ROW()-33+1)/12+0.02,"Ahead of Plan",IF(H38>=(ROW()-33+1)/12-0.02,"On Track","Behind Plan - Review Required")) -> On Track
A39: April | B39: =D23 -> 1020 | C39: =($B$9+($B$8-$B$9)*(ROW()-33)/11) -> 0.10287075 | D39: =B39*C39 -> 104.92817 | E39: =B39-D39 -> 915.07183 | F39: =F38+B39 -> 6960 | G39: =G38+D39 -> 666.92975 | H39: =F39/$B$5 -> 0.58 | I39: =IF(H39>=(ROW()-33+1)/12+0.02,"Ahead of Plan",IF(H39>=(ROW()-33+1)/12-0.02,"On Track","Behind Plan - Review Required")) -> On Track
A40: May | B40: =D24 -> 1080 | C40: =($B$9+($B$8-$B$9)*(ROW()-33)/11) -> 0.1052966 | D40: =B40*C40 -> 113.72033 | E40: =B40-D40 -> 966.27967 | F40: =F39+B40 -> 8040 | G40: =G39+D40 -> 780.65008 | H40: =F40/$B$5 -> 0.67 | I40: =IF(H40>=(ROW()-33+1)/12+0.02,"Ahead of Plan",IF(H40>=(ROW()-33+1)/12-0.02,"On Track","Behind Plan - Review Required")) -> On Track
A41: June | B41: =D25 -> 960 | C41: =($B$9+($B$8-$B$9)*(ROW()-33)/11) -> 0.10772245 | D41: =B41*C41 -> 103.41355 | E41: =B41-D41 -> 856.58645 | F41: =F40+B41 -> 9000 | G41: =G40+D41 -> 884.06364 | H41: =F41/$B$5 -> 0.75 | I41: =IF(H41>=(ROW()-33+1)/12+0.02,"Ahead of Plan",IF(H41>=(ROW()-33+1)/12-0.02,"On Track","Behind Plan - Review Required")) -> On Track
A42: July | B42: =D26 -> 840 | C42: =($B$9+($B$8-$B$9)*(ROW()-33)/11) -> 0.1101483 | D42: =B42*C42 -> 92.524573 | E42: =B42-D42 -> 747.47543 | F42: =F41+B42 -> 9840 | G42: =G41+D42 -> 976.58821 | H42: =F42/$B$5 -> 0.82 | I42: =IF(H42>=(ROW()-33+1)/12+0.02,"Ahead of Plan",IF(H42>=(ROW()-33+1)/12-0.02,"On Track","Behind Plan - Review Required")) -> On Track
A43: August | B43: =D27 -> 960 | C43: =($B$9+($B$8-$B$9)*(ROW()-33)/11) -> 0.11257415 | D43: =B43*C43 -> 108.07118 | E43: =B43-D43 -> 851.92882 | F43: =F42+B43 -> 10800 | G43: =G42+D43 -> 1084.6594 | H43: =F43/$B$5 -> 0.9 | I43: =IF(H43>=(ROW()-33+1)/12+0.02,"Ahead of Plan",IF(H43>=(ROW()-33+1)/12-0.02,"On Track","Behind Plan - Review Required")) -> On Track
...

Sheet DASHBOARD
B1: SIEMENS MOBILITY — FY2026 OPERATIONS FINANCE DASHBOARD
B3: FY2026 REVENUE TARGET | D3: FORECAST PROFIT FY2026 | F3: AVG FORECAST MARGIN | H3: MARGIN GAP TO CLOSE
B5: =TEXT(FORECAST!B47,"#,##0")&"€M" -> 12,000€M | D5: =TEXT(FORECAST!B48,"#,##0")&"€M" -> 1,223€M | F5: =FORECAST!B49 -> 0.10188828 | H5: =FORECAST!B12 -> 0.026684346
B7: Backlog Conversion | D7: =TEXT(FORECAST!B52,"0.0%")&" vs FY2025" -> 11.3% vs FY2025 | F7: =IF(FORECAST!B49>=FORECAST!B6, "Above Target","Below Target") -> Above Target | H7: vs FY2025 actual performance
B10: VARIANCE BRIDGE DATA
B11: Category | D11: €M
B12: FY2024 Profit | D12: =ANALYSIS!C5 -> 1013
B13: Volume Effect | D13: =ANALYSIS!C6 -> 90.832925
B14: Margin/Cost Effect | D14: =ANALYSIS!C7 -> -4.8329247
B15: Severance Impact | D15: =ANALYSIS!C8 -> -7
B16: Residual | D16: =ANALYSIS!C9 -> 7
B17: FY2025 Profit | D17: =ANALYSIS!C12 -> 1099
B19: MONTHLY FORECAST DATA
B20: Month | C20: Revenue | D20: Margin %
B21: =FORECAST!A33 -> October | C21: =FORECAST!B33 -> 960 | D21: =FORECAST!C33 -> 0.088315654
B22: =FORECAST!A34 -> November | C22: =FORECAST!B34 -> 1020 | D22: =FORECAST!C34 -> 0.090741504
B23: =FORECAST!A35 -> December | C23: =FORECAST!B35 -> 840 | D23: =FORECAST!C35 -> 0.093167353
B24: =FORECAST!A36 -> January | C24: =FORECAST!B36 -> 900 | D24: =FORECAST!C36 -> 0.095593203
B25: =FORECAST!A37 -> February | C25: =FORECAST!B37 -> 1080 | D25: =FORECAST!C37 -> 0.098019053
B26: =FORECAST!A38 -> March | C26: =FORECAST!B38 -> 1140 | D26: =FORECAST!C38 -> 0.1004449
B27: =FORECAST!A39 -> April | C27: =FORECAST!B39 -> 1020 | D27: =FORECAST!C39 -> 0.10287075
B28: =FORECAST!A40 -> May | C28: =FORECAST!B40 -> 1080 | D28: =FORECAST!C40 -> 0.1052966
B29: =FORECAST!A41 -> June | C29: =FORECAST!B41 -> 960 | D29: =FORECAST!C41 -> 0.10772245
B30: =FORECAST!A42 -> July | C30: =FORECAST!B42 -> 840 | D30: =FORECAST!C42 -> 0.1101483
B31: =FORECAST!A43 -> August | C31: =FORECAST!B43 -> 960 | D31: =FORECAST!C43 -> 0.11257415
B32: =FORECAST!A44 -> September | C32: =FORECAST!B44 -> 1200 | D32: =FORECAST!C44 -> 0.115
B45: EXECUTIVE SUMMARY - KEY SIGNALS
B46: Metric | F46: Value | H46: Signal
B47: FY2026 Revenue Target | F47: =TEXT(FORECAST!B47,"#,##0") & " €M" -> 12,000 €M | H47: Full backlog conversion require
B48: FY2026 Forecast Profit | F48: =TEXT(FORECAST!B48,"#,##0") & " €M" -> 1,223 €M | H48: =IF(FORECAST!B48>Data!C6, "Above FY2025 — on track","Below FY2025 — review required") -> Above FY2025 — on track
B49: Profit Improvement | F49: =TEXT(FORECAST!B51,"#,##0") & " €M" -> 124 €M | H49: =TEXT(FORECAST!B52,"0.0% ") & "growth vs FY2025" -> 11.3% growth vs FY2025
B50: Average Forecast Margin | F50: =TEXT(FORECAST!B49,"0.00%") -> 10.19% | H50: =IF(FORECAST!B49>=FORECAST!B6,"Within target range 10-13%","Below minimum target of 10%") -> Within target range 10-13%
B51: CAPEX Health Ratio | F51: =TEXT(ANALYSIS!C16,"0.00") -> 0.82 | H51: =ANALYSIS!D16 -> Caution - assets aging faster than investment
B52: Backlog Coverage | F52: =TEXT(ANALYSIS!C20,"0.0")&" years" -> 4.2 years | H52: Production capacity is the constraint not sales
B53: Labor Cost Ratio | F53: =TEXT(ANALYSIS!B27,"0%")&" of total costs" -> 44% of total costs | H53: Source: Note 27 FY2025 Annual Report
B54: Source: Siemens FY2025 Annual Report |Independent financial analysis — not affiliated with or endorsed by Siemens

Sheet SOURCES
A1: SOURCE DOCUMENTATION
A2: All data used in this financial model
A4: # | B4: Source Document | C4: Section/Note | D4: Data Used | E4: Applied In
A5: 1 | B5: Siemens FY2025 Annual Report | C5: Mobility Segment Table | D5: Revenue €12,444M, Profit €1,099M, Orders €16,994M | E5: DATA sheet
A6: 2 | B6: Siemens FY2025 Annual Report | C6: Mobility Segment Table | D6: FY2024 Revenue €11,420M, Profit €1,013M | E6: DATA sheet
A7: 3 | B7: Siemens FY2025 Annual Report | C7: Mobility Segment Table | D7: Order Backlog €52B, FY2026 conversion €12B | E7: DATA, FORECAST
A8: 4 | B8: Siemens FY2025 Annual Report | C8: Note 29 Segment Data | D8: CAPEX €222M, Depreciation €270M, FCF €1,027M | E8: DATA sheet
A9: 5 | B9: Siemens FY2025 Annual Report | C9: Note 27 Personnel Costs | D9: Group personnel costs €31,598M — basis for 44% labor ratio | E9: ANALYSIS Block 3
A10: 6 | B10: Siemens FY2025 Annual Report | C10: Consolidated P&L | D10: Group revenue €78,914M — denominator for labor ratio | E10: ANALYSIS Block 3
A11: 7 | B11: Siemens FY2025 Annual Report | C11: Mobility Segment Table | D11: Severance €32M FY2025, €25M FY2024 | E11: ANALYSIS variance bridge
A12: 8 | B12: Siemens FY2025 Annual Report | C12: Combined Management Report | D12: FY2026 Mobility margin target 8-10%, mid-term target 10-13% | E12: FORECAST
B14: METHODOLOGY NOTES
B15: Labor cost ratio of 44% derived by applying Group personnel cost ratio to Mobility total costs. Actual plant-level ratios would replace this on day one.
B16: Seasonality weights based on manufacturing industry patterns. Actual Lexington plant production schedule would replace these.
B17: Margin improvement ramp assumes linear progression from FY2025 actual to FY2026 base target. Actual improvement depends on operational execution.

Sheet TOOLS
A1: XLOOKUP DEMONSTRATION
A2: Scenario: Looking up monthly forecast data by month name
A3: Reference table | B3: Month | C3: Revenue EM | D3: Margin %
B4: October | C4: =FORECAST!B33 -> 960 | D4: =FORECAST!C33 -> 0.088315654
B5: November | C5: =FORECAST!B34 -> 1020 | D5: =FORECAST!C34 -> 0.090741504
B6: December | C6: =FORECAST!B35 -> 840 | D6: =FORECAST!C35 -> 0.093167353
B7: January | C7: =FORECAST!B36 -> 900 | D7: =FORECAST!C36 -> 0.095593203
B8: February | C8: =FORECAST!B37 -> 1080 | D8: =FORECAST!C37 -> 0.098019053
B9: March | C9: =FORECAST!B38 -> 1140 | D9: =FORECAST!C38 -> 0.1004449
B10: April | C10: =FORECAST!B39 -> 1020 | D10: =FORECAST!C39 -> 0.10287075
B11: May | C11: =FORECAST!B40 -> 1080 | D11: =FORECAST!C40 -> 0.1052966
B12: June | C12: =FORECAST!B41 -> 960 | D12: =FORECAST!C41 -> 0.10772245
B13: July | C13: =FORECAST!B42 -> 840 | D13: =FORECAST!C42 -> 0.1101483
B14: August | C14: =FORECAST!B43 -> 960 | D14: =FORECAST!C43 -> 0.11257415
B15: September | C15: =FORECAST!B44 -> 1200 | D15: =FORECAST!C44 -> 0.115
A18: MONTH LOOKUP TOOL
A19: Type any month name below
A20: March
A21: Revenue for selected month:
A22: =_xlfn.XLOOKUP(A20, B4:B15, C4:C15, "Month not found") -> 1140
A23: Margin for selected month:
A24: =_xlfn.XLOOKUP(A20,B4:B15,D4:D15, "Month not found") -> 0.1004449
A25: Monthly Average Revenue
A26: =IF(A22="Month not found", "N/A", AVERAGE(C4:C15)) -> 1000
A27: Performance:
A28: =IF(A22= "Month not found","N/A", IF(A22>A26, "Above average revenue month", "Below average revenue month")) -> Above average revenue month
